Workbook
Name tabletax: 会社退職金!$Q$14:$T$19

Sheet 入力
A1: 通常の退職金＋確定拠出年金：重複調整シミュレーション
A2: ※本Excelでは「企業型DC」と記載していますが、退職所得として一時金で受け取る場合の税務上の重複調整については、iDeCo（個人型確定拠出年金）も基本的に同様の扱いとなります。
A3: 企業型DCを利用していない方で、iDeCoの一時金を受け取る場合は、「企業型DC」を「iDeCo」と読み替えて、そのままご利用ください。
A5: 入力項目 | B5: 入力値 | C5: 単位・説明
A6: 会社退職金の勤続開始日 | B6: 32599 | C6: 日付。実際の退職金規程に合わせて変更 | E6: 誕生日 | F6: 25689
A7: 会社退職金の退職日 | B7: 49459 | C7: 日付。65歳退職予定日等に変更 | E7: 退職時年齢 | F7: =DATEDIF($F$6, B7, "Y") & "歳" & DATEDIF($F$6, B7, "YM") & "ヶ月" -> 65歳0ヶ月
A8: 会社退職金の受取日 | B8: 49459 | C8: 日付
A9: 会社退職金額 | B9: 1000000 | C9: 円
A10: 企業型DCの控除計算用加入開始日 | B10: 44652 | C10: 制度資料で確認した期間を入力
A11: 企業型DCの控除計算用加入終了日 | B11: 49825 | C11: 制度資料で確認した期間を入力 | E11: DC加入終了日 | F11: =DATEDIF($F$6, B11, "Y") & "歳" & DATEDIF($F$6, B11, "YM") & "ヶ月" -> 66歳0ヶ月
A12: 企業型DC一時金の受取日 | B12: 46172 | C12: 日付。比較シートで変更可能
A13: 企業型DC一時金額 | B13: 10000000 | C13: 円。仮入力。実際の残高に変更
A14: 参考：会社退職金→DCの調整対象期間 | B14: 19 | C14: 年。会社退職金を先に受け取り、その後DC一時金を受け取る場合の確認用。重複期間そのものではありません。
A15: 参考：DC→会社退職金の調整対象期間 | B15: 9 | C15: 年。2026年以後に受け取るDC一時金が先で、通常の退職金が後の場合の確認用。適用条件の確認が必要です。
A16: 今回の入力ケースの判定
A17: 受取順序 | B17: =IF(OR(B8="",B12=""),"",IF(B12<B8,"DC → 会社退職金",IF(B12>B8,"会社退職金 → DC","同日受取：要確認"))) -> DC → 会社退職金 | C17: 受取日を比較して自動判定
A18: 自動計算 | B18: 結果 | C18: 説明
A19: 会社退職金の勤続年数 | B19: =IF(OR(B6="",B7=""),"",DATEDIF(B6,B7+1,"Y")+IF(DATEDIF(B6,B7+1,"YM")+DATEDIF(B6,B7+1,"MD")>0,1,0)) -> 47 | C19: 端数は1年に切上げる簡易計算
A20: 会社退職金の退職所得控除額 | B20: =IF(B19="","",IF(B19<=20,MAX(800000,400000*B19),8000000+700000*(B19-20))) -> 26900000 | C20: 通常の退職所得控除
A21: DCの加入年数 | B21: =IF(OR(B10="",B11=""),"",DATEDIF(B10,B11+1,"Y")+IF(DATEDIF(B10,B11+1,"YM")+DATEDIF(B10,B11+1,"MD")>0,1,0)) -> 15 | C21: 制度資料で確認した期間を入力
A22: DCの退職所得控除額 | B22: =IF(B21="","",IF(B21<=20,MAX(800000,400000*B21),8000000+700000*(B21-20))) -> 6000000 | C22: 重複調整前
A23: 重複調整の確認期間 | B23: =IF(B17="DC → 会社退職金",9,IF(B17="会社退職金 → DC",19,"")) -> 9 | C23: DC→会社退職金は9年、会社退職金→DCは19年。
A24: 比較シートとの関係 | B24: 「受取時期比較」は入力B10の値を増やす入力欄ではなく、複数の受取時期を並べて比較する別計算です。 | C24: 入力B10は今回の1ケース用。
A25: 注意 | B25: 通常の退職金と企業型DC一時金について、退職所得控除をそれぞれ適用できる可能性と、重複期間による控除額調整の影響を検討する試算用です。受取時期を変えることで税引後の手取り額が増える可能性がありますが、必ず有利になるとは限りません。
A27: 設計上の注意 | B27: B12・B13は重複期間そのものではなく、法令上の確認対象となり得る期間を示す参考値です。実際の重複期間は、退職金・DCの加入期間、受取日、制度移行・資産移換、過去の退職手当等を確認して計算する必要があります。
A30: 制度の考え方・このシミュレーションの目的
A31: 退職所得控除を2回受けられる可能性 | B31: 通常の退職金と企業型DCの老齢給付金（一時金）は、受取時期や制度上の要件によって、それぞれ退職所得控除の計算対象となり得ます。ただし、過去に受け取った退職手当等との勤続期間の重複がある場合は、控除額の重複を避けるための調整が行われます。
A32: 重複調整の考え方 | B32: 本年分の退職手当等の勤続期間と、一定期間内に受け取った前の退職手当等の勤続期間に重複がある場合、その重複期間に対応する退職所得控除額相当額が、本年分の退職所得控除額から差し引かれることがあります。
A33: 受取時期を検討する理由 | B33: 退職金と企業型DC一時金の受取時期を変えると、法令上の確認対象となる期間や勤続期間の重複状況が変わる可能性があります。その結果、調整後の退職所得控除額、課税退職所得金額、税額、税引後の手取り額が変わる可能性があります。
A34: 「利益が増える」の意味 | B34: 受取時期を調整することで、重複調整による退職所得控除額の減少を抑えられる場合があり、その場合は税負担が減り、税引後の手取り額が増える可能性があります。ただし、受取時期を変えれば必ず有利になるわけではなく、DCの運用結果、受取可能年齢、加入期間、他の退職手当等、税率なども影響します。
A35: このExcelで確認すること | B35: 会社退職金と企業型DC一時金の受取順序・受取時期を比較し、重複調整の影響を検討するための材料を整理します。現状の重複期間欄は確認用の簡易値であり、申告税額を確定するものではありません。
A36: 主な参照先 | B36: 国税庁 No.2735「同じ年に2か所以上から退職手当等が支払われるとき」／国税庁 No.1420「退職金を受け取ったとき（退職所得）」
A37: 重要な注意 | B37: 「19年」「9年」はすべてのケースに一律適用される期間ではありません。受取年、退職手当等の種類、DC一時金の支払時期、過去の受取状況などにより適用関係が異なるため、実際の計算では国税庁の規定と制度資料を確認してください。
A38: github | B38: https://github.com/pukkunk/retirement-income-tax-dc-excel/blob/main/README.md

Sheet 重複調整計算
A1: 重複調整計算（今回の入力ケース）
A3: 項目 | B3: 今回の入力ケース | C3: 説明 | D3: 計算根拠 | E3: 確認
A4: 先に受け取る制度 | B4: =IF(入力!B17="DC → 会社退職金","企業型DC",IF(入力!B17="会社退職金 → DC","会社退職金","要確認")) -> 企業型DC | C4: 受取日が早い制度 | D4: 受取日比較
A5: 先の受取日 | B5: =IF(OR(入力!B8="",入力!B12=""),"",MIN(入力!B8,入力!B12)) -> 46172 | C5: 受取日の早い方 | D5: 入力シート
A6: 後の受取日 | B6: =IF(OR(入力!B8="",入力!B12=""),"",MAX(入力!B8,入力!B12)) -> 49459 | C6: 受取日の遅い方 | D6: 入力シート
A7: 先の一時金額 | B7: =IF(B4="企業型DC",入力!B13,IF(B4="会社退職金",入力!B9,"")) -> 10000000 | C7: 先に受け取る制度の金額 | D7: 入力シート
A8: 先の控除計算年数 | B8: =IF(B4="企業型DC",入力!B21,IF(B4="会社退職金",入力!B19,"")) -> 15 | C8: 先に受け取る制度の控除計算年数 | D8: 入力シート
A9: 先の本来の退職所得控除 | B9: =IF(B4="企業型DC",入力!B22,IF(B4="会社退職金",入力!B20,"")) -> 6000000 | C9: 重複調整前 | D9: 退職所得控除表
A10: 先の金額が控除未満か | B10: =IF(B7="","",IF(B7<B9,"該当","非該当")) -> 非該当 | C10: 前の一時金額と本来の控除額を比較 | D10: 国税庁No.2732
A11: 前の退職手当等の換算年数 | B11: =IF(B10="該当",ROUNDDOWN(IF(B7<=8000000,B7/400000,(B7-8000000)/700000+20),0),B8) -> 15 | C11: 控除未満の場合に金額から換算 | D11: 国税庁No.2732 | E11: 要確認
A12: 重複調整の確認期間 | B12: =入力!B23 -> 9 | C12: DC→会社=9年、会社→DC=19年 | D12: 受取順序から自動判定
A13: 重複調整の対象となる受取間隔 | B13: =IF(OR(B5="",B6="",B12=""),"",IF(YEARFRAC(B5,B6,1)<=B12,"対象","対象外")) -> 対象外 | C13: 前の退職手当等の受取日が確認期間内か | D13: 受取日・確認期間 | F13: 要確認
A14: 実際の重複期間 | B14: =IF(B13="対象","要計算（開始日・終了日で算定）",IF(B13="対象外",0,"要確認")) -> 0 | C14: 重複がある場合だけ、両制度の期間から算定 | D14: 国税庁No.2732 | E14: 要計算 | F14: 要確認
A15: 後の調整後控除額 | B15: =IF(B14=0,IF(B4="企業型DC",入力!B22,入力!B20),"要計算") -> 6000000 | C15: 重複なしなら本来の控除額をそのまま使用 | D15: 重複期間がある場合のみ調整 | E15: 要確認 | F15: 要確認
A16: 計算の分岐 | B16: 重複なし → 通常の退職所得控除。重複あり → 重複期間に応じた控除額調整へ切替。 | C16: 今回の設計上の重要ポイント
A17: 比較シートとの関係 | B17: このシートは入力B10による「1ケース」の計算。複数のDC受取時期を並べるのは「受取時期比較」です。
A19: 重要 | B19: 実際の重複期間は、各制度の開始日・終了日と、前の退職手当等の受取時期を基に確定する必要があります。ここでは重複なしの場合は通常控除に戻し、重複ありの場合だけ詳細計算へ切り替える構造にしています。
A23: 制度説明
A24: 控除を2回受けられる可能性 | B24: 会社退職金と企業型DC一時金は、それぞれ退職所得控除の対象となり得ますが、重複期間がある場合は控除額の調整が必要です。
A25: 受取時期の調整効果 | B25: 受取時期によって調整対象となる期間や重複状況が変わり、調整後控除額・課税額・手取り額が変わる可能性があります。
A26: 注意 | B26: このシートの重複期間は簡易的な確認値です。実際の申告用には、受取日、加入期間、制度移行・資産移換、過去の退職手当等を確認したうえで、法令に沿った計算が必要です。

Sheet 受取時期比較
A1: 受取時期比較（入力ケースとは別の複数ケース比較）
A2: 目的 | C2: DC受取日を変えた場合の受取順序・9年/19年判定と、手取り差を比較するための参考表。ここは入力シートの1個の受取日とは別物です。
A3: ケース | B3: DC控除計算用加入終了日 | C3: DC受取日 | D3: 会社退職金受取日 | E3: DC金額 | F3: 会社退職金額 | G3: 受取順序 | H3: 確認期間 | I3: 重複調整対象 | J3: 前の退職手当等金額 | K3: 前の本来控除額 | L3: 前の退職手当等が控除額未満 | M3: 前の換算年数 | N3: 重複期間開始日 | O3: 重複期間終了日 | P3: 実際の重複年度 | Q3: 会社調整後控除 | R3: DC調整後控除 | S3: 会社課税退職所得 | T3: DC課税退職所得 | U3: 会社所得税率 | V3: 会社所得税控除額 | W3: 会社所得税等 | X3: DC所得税率 | Y3: DC所得税控除額 | Z3: DC所得税等 | AA3: 会社住民税 | AB3: DC住民税 | AC3: 合計税額 | AD3: 税引後手取り | AE3: 計算内容・根拠 | AF3: 機械的換算年数（参考） | AG3: 適用年数 | AH3: 勤続年数 | AI3: 退職所得控除額 | AJ3: 課税退職所得 | AK3: 同年所得税率 | AL3: 所得税控除額 | AM3: 同年所得税等 | AN3: 同年住民税 | AO3: 合計税額 | AP3: 同年税引後手取り | AQ3: 手取り
A4: 1 | B4: 47664 | C4: 47664 | D4: =入力!$B$8 -> 49459 | E4: =入力!$B$13 -> 10000000 | F4: =入力!$B$9 -> 1000000 | G4: =IF(OR(C4="",D4=""),"",IF(YEAR(C4)=YEAR(D4),"同年受取",IF(C4<D4,"DC → 会社退職金","会社退職金 → DC"))) -> DC → 会社退職金 | H4: =IF(OR(G4="同年受取",G4=""),"",IF(G4="DC → 会社退職金",9,19)) -> 9 | I4: =IF(G4="同年受取","同年合算",IF(G4="","",IF(AND(MIN(C4,D4)<DATE(YEAR(MAX(C4,D4)),1,1),MIN(C4,D4)>=DATE(YEAR(MAX(C4,D4))-H4,1,1)),"対象","対象外"))) -> 対象 | J4: =IF(G4="同年受取","",IF(G4="DC → 会社退職金",E4,IF(G4="会社退職金 → DC",F4,""))) -> 10000000 | K4: =IF(G4="同年受取","", IF(G4="DC → 会社退職金", _xlfn.LET( _xlpm.DC開始,入力!$B$10, _xlpm.DC終了,B4, _xlpm.年数,IF(DATEDIF(_xlpm.DC開始,_xlpm.DC終了+1,"M")=0,1,CEILING(DATEDIF(_xlpm.DC開始,_xlpm.DC終了+1,"M")/12,1)), IF(_xlpm.年数<=20,MAX(400000*_xlpm.年数,800000),8000000+700000*(_xlpm.年数-20)) ), IF(G4="会社退職金 → DC", _xlfn.LET( _xlpm.会社控除額,入力!$B$20, _xlpm.会社控除額 ), ""))) -> 3600000 | L4: =IF(OR(J4="",K4=""),"",IF(J4<K4,"該当","非該当")) -> 非該当 | M4: =_xlfn.LET( _xlpm.前退,J4, _xlpm.前控,K4, _xlpm.会勤年,入力!$B$19, IF(G4="同年受取","", IF(OR(_xlpm.前退="",_xlpm.前控=""),"", IF(_xlpm.前退<_xlpm.前控, ROUNDDOWN(IF(_xlpm.前退<=8000000,_xlpm.前退/400000,(_xlpm.前退-8000000)/700000+20),0), IF(G4="DC → 会社退職金", _xlfn.LET( _xlpm.DC開始,入力!$B$10, _xlpm.DC終了,B4, DATEDIF(_xlpm.DC開始,_xlpm.DC終了+1,"Y") +IF(DATEDIF(_xlpm.DC開始,_xlpm.DC終了+1,"YD")>0,1,0) ), IF(G4="会社退職金 → DC", _xlpm.会勤年, "" ) ) ) ) ) ) -> 9 | N4: =IF(G4="同年受取","",IF(I4<>"対象","",MAX(IF(G4="DC → 会社退職金",入力!$B$10,入力!$B$6),IF(G4="DC → 会社退職金",入力!$B$6,入力!$B$10)))) -> 44652 | O4: =_xlfn.LET( _xlpm.受取順,G4, _xlpm.対象,I4, _xlpm.前退,J4, _xlpm.前控,K4, _xlpm.前換算年,M4, _xlpm.会社開始,入力!$B$6, _xlpm.会社終了,入力!$B$7, _xlpm.DC開始,入力!$B$10, _xlpm.DC終了,B4, _xlpm.重複終了上限,IF( _xlpm.受取順="DC → 会社退職金", _xlpm.DC終了, _xlpm.会社終了 ), _xlpm.換算期間終了,IF( _xlpm.前退<_xlpm.前控, EDATE( IF( _xlpm.受取順="DC → 会社退職金", _xlpm.DC開始, _xlpm.会社開始 ), _xlpm.前換算年*12 )-1, _xlpm.重複終了上限 ), IF( _xlpm.受取順="同年受取", "", IF( _xlpm.対象<>"対象", "", MIN( _xlpm.重複終了上限, _xlpm.換算期間終了 ) ) ) ) -> 47664 | P4: =_xlfn.LET( _xlpm.重複開始,N4, _xlpm.重複終了,O4, IF( G4="同年受取", "", IF( OR(_xlpm.重複開始="",_xlpm.重複終了="",_xlpm.重複開始>_xlpm.重複終了), 0, DATEDIF(_xlpm.重複開始,_xlpm.重複終了+1,"Y") ) ) ) -> 8 | Q4: =IF(G4="同年受取","", _xlfn.LET( _xlpm.受取順,G4, _xlpm.実重複年,P4, _xlpm.会社本来控除,入力!$B$20, _xlpm.重複控除,IF( _xlpm.実重複年<=20, MAX(800000,400000*_xlpm.実重複年), 8000000+700000*(_xlpm.実重複年-20) ), IF( _xlpm.受取順="DC → 会社退職金", IF( I4="対象", MAX(0,_xlpm.会社本来控除-_xlpm.重複控除), _xlpm.会社本来控除 ), _xlpm.会社本来控除 ) )) -> 23700000 | R4: =IF(G4="同年受取","", _xlfn.LET( _xlpm.受取順,G4, _xlpm.DC開始,入力!$B$10, _xlpm.DC終了,B4, _xlpm.実重複年,P4, _xlpm.DC年数,IF( DATEDIF(_xlpm.DC開始,_xlpm.DC終了+1,"M")=0, 1, CEILING(DATEDIF(_xlpm.DC開始,_xlpm.DC終了+1,"M")/12,1) ), _xlpm.DC本来控除,IF( _xlpm.DC年数<=20, 400000*_xlpm.DC年数, 8000000+700000*(_xlpm.DC年数-20) ), _xlpm.重複控除,IF( _xlpm.実重複年=0, 0, IF( _xlpm.実重複年<=20, 400000*_xlpm.実重複年, 8000000+700000*(_xlpm.実重複年-20) ) ), IF( _xlpm.受取順="会社退職金 → DC", IF( I4="対象", MAX(0,_xlpm.DC本来控除-_xlpm.重複控除), _xlpm.DC本来控除 ), _xlpm.DC本来控除 ) ) ) -> 3600000 | S4: =IF(G4="同年受取","",IF(OR(G4="",G4="同日受取：要確認"),"",ROUNDDOWN(MAX(0,(F4-Q4)/2),-3))) -> 0 | T4: =IF(G4="同年受取","",IF(OR(G4="",G4="同日受取：要確認"),"",ROUNDDOWN(MAX(0,(E4-R4)/2),-3))) -> 3200000 | U4: =IF(OR(G4="同年受取",S4=""),"",VLOOKUP(S4,税率表!$A$2:$C$8,2,TRUE)) -> 0.05 | V4: =IF(U4="","",VLOOKUP(S4,税率表!$A$2:$C$8,3,TRUE)) -> 0 | W4: =IF(U4="","",ROUNDDOWN(MAX(0,S4*U4-V4)*1.021,0)) -> 0 | X4: =IF(OR(G4="同年受取",T4=""),"",VLOOKUP(T4,税率表!$A$2:$C$8,2,TRUE)) -> 0.1 | Y4: =IF(X4="","",VLOOKUP(T4,税率表!$A$2:$C$8,3,TRUE)) -> 97500 | Z4: =IF(X4="","",ROUNDDOWN(MAX(0,T4*X4-Y4)*1.021,0)) -> 227172 | AA4: =IF(G4="同年受取","",IF(S4="","",ROUNDDOWN(S4*10%,0))) -> 0 | AB4: =IF(G4="同年受取","",IF(T4="","",ROUNDDOWN(T4*10%,0))) -> 320000 | AC4: =IF(G4="同年受取","",IF(OR(W4="",Z4=""),"",SUM(W4,Z4,AA4,AB4))) -> 547172 | AD4: =IF(G4="同年受取","",IF(AC4="","",E4+F4-AC4)) -> 10452828 | AE4: =IF(G4="同年受取","No.2735：同年の退職手当等を合算し、2制度の勤続期間を統合して退職所得控除額を計算",IF(I4="対象","No.2732：確認期間→前の金額/控除→換算年数→重複年度→後の控除調整→課税退職所得→税額",IF(G4="","",IF(I4="対象外","No.2732：確認期間外→重複調整なし→通常控除→課税退職所得→税額","")))) -> No.2732：確認期間→前の金額/控除→換算年数→重複年度→後の控除調整→課税退職所得→税額 | AF4: =IF(OR(J4="",K4="",G4="同年受取"),"",ROUNDDOWN(IF(J4<=8000000,J4/400000,(J4-8000000)/700000+20),0)) -> 22 | AG4: =IF(OR(J4="",K4="",G4="同年受取"),"",IF(J4<K4,AF4,IF(G4="DC → 会社退職金",入力!$B$21,入力!$B$19))) -> 15 | AH4: =IF(G4<>"同年受取","",_xlfn.LET( _xlpm.A開始,入力!$B$6, _xlpm.A終了,入力!$B$7, _xlpm.B開始,入力!$B$10, _xlpm.B終了,B4, _xlpm.A日数,_xlpm.A終了-_xlpm.A開始+1, _xlpm.B日数,_xlpm.B終了-_xlpm.B開始+1, IF( OR(_xlpm.A終了<_xlpm.B開始,_xlpm.B終了<_xlpm.A開始), IF(_xlpm.A日数>=_xlpm.B日数, DATEDIF(_xlpm.A開始,_xlpm.A終了+1,"Y")+IF(DATEDIF(_xlpm.A開始,_xlpm.A終了+1,"YD")>0,1,0), DATEDIF(_xlpm.B開始,_xlpm.B終了+1,"Y")+IF(DATEDIF(_xlpm.B開始,_xlpm.B終了+1,"YD")>0,1,0) ), DATEDIF(MIN(_xlpm.A開始,_xlpm.B開始),MAX(_xlpm.A終了,_xlpm.B終了)+1,"Y") +IF(DATEDIF(MIN(_xlpm.A開始,_xlpm.B開始),MAX(_xlpm.A終了,_xlpm.B終了)+1,"YD")>0,1,0) ) )) | AI4: =IF(G4<>"同年受取","",IF(AH4<=20,MAX(400000*AH4,800000),8000000+700000*(AH4-20))) | AJ4: =IF(G4<>"同年受取","",MAX(0,FLOOR((E4+F4-AI4)/2,1000))) | AK4: =IF(G4<>"同年受取","",VLOOKUP(AJ4,tabletax,3,TRUE)) | AL4: =IF(G4<>"同年受取","",VLOOKUP(AJ4,tabletax,4,TRUE)) | AM4: =IF(G4<>"同年受取","",FLOOR((AJ4*AK4-AL4)*1.021,1)) | AN4: =IF(G4<>"同年受取","",FLOOR(AJ4*0.1,100)) | AO4: =IF(G4<>"同年受取","",AM4+AN4) | AP4: =IF(G4<>"同年受取","",IF(AM4="","",E4+F4-AO4)) | AQ4: =IF(AD4<>"",AD4,IF(AP4<>"",AP4)) -> 10452828
A5: 2 | B5: 48029 | C5: 48029 | D5: =入力!$B$8 -> 49459 | E5: =入力!$B$13 -> 10000000 | F5: =入力!$B$9 -> 1000000 | G5: =IF(OR(C5="",D5=""),"",IF(YEAR(C5)=YEAR(D5),"同年受取",IF(C5<D5,"DC → 会社退職金","会社退職金 → DC"))) -> DC → 会社退職金 | H5: =IF(OR(G5="同年受取",G5=""),"",IF(G5="DC → 会社退職金",9,19)) -> 9 | I5: =IF(G5="同年受取","同年合算",IF(G5="","",IF(AND(MIN(C5,D5)<DATE(YEAR(MAX(C5,D5)),1,1),MIN(C5,D5)>=DATE(YEAR(MAX(C5,D5))-H5,1,1)),"対象","対象外"))) -> 対象 | J5: =IF(G5="同年受取","",IF(G5="DC → 会社退職金",E5,IF(G5="会社退職金 → DC",F5,""))) -> 10000000 | K5: =IF(G5="同年受取","", IF(G5="DC → 会社退職金", _xlfn.LET( _xlpm.DC開始,入力!$B$10, _xlpm.DC終了,B5, _xlpm.年数,IF(DATEDIF(_xlpm.DC開始,_xlpm.DC終了+1,"M")=0,1,CEILING(DATEDIF(_xlpm.DC開始,_xlpm.DC終了+1,"M")/12,1)), IF(_xlpm.年数<=20,MAX(400000*_xlpm.年数,800000),8000000+700000*(_xlpm.年数-20)) ), IF(G5="会社退職金 → DC", _xlfn.LET( _xlpm.会社控除額,入力!$B$20, _xlpm.会社控除額 ), ""))) -> 4000000 | L5: =IF(OR(J5="",K5=""),"",IF(J5<K5,"該当","非該当")) -> 非該当 | M5: =_xlfn.LET( _xlpm.前判定,L5, _xlpm.前退,J5, _xlpm.前控,K5, _xlpm.会勤年,入力!$B$19, IF(G5="同年受取","", IF(OR(_xlpm.前退="",_xlpm.前控=""),"", IF(_xlpm.前判定="該当", ROUNDDOWN(IF(_xlpm.前退<=8000000,_xlpm.前退/400000,(_xlpm.前退-8000000)/700000+20),0), IF(G5="DC → 会社退職金", _xlfn.LET( _xlpm.DC開始,入力!$B$10, _xlpm.DC終了,B5, DATEDIF(_xlpm.DC開始,_xlpm.DC終了+1,"Y") +IF(DATEDIF(_xlpm.DC開始,_xlpm.DC終了+1,"YD")>0,1,0) ), IF(G5="会社退職金 → DC", _xlpm.会勤年, "" ) ) ) ) ) ) -> 10 | N5: =IF(G5="同年受取","",IF(I5<>"対象","",MAX(IF(G5="DC → 会社退職金",入力!$B$10,入力!$B$6),IF(G5="DC → 会社退職金",入力!$B$6,入力!$B$10)))) -> 44652 | O5: =_xlfn.LET( _xlpm.受取順,G5, _xlpm.対象,I5, _xlpm.前退,J5, _xlpm.前控,K5, _xlpm.前換算年,M5, _xlpm.会社開始,入力!$B$6, _xlpm.会社終了,入力!$B$7, _xlpm.DC開始,入力!$B$10, _xlpm.DC終了,B5, _xlpm.重複終了上限,IF( _xlpm.受取順="DC → 会社退職金", _xlpm.DC終了, _xlpm.会社終了 ), _xlpm.換算期間終了,IF( _xlpm.前退<_xlpm.前控, EDATE( IF( _xlpm.受取順="DC → 会社退職金", _xlpm.DC開始, _xlpm.会社開始 ), _xlpm.前換算年*12 )-1, _xlpm.重複終了上限 ), IF( _xlpm.受取順="同年受取", "", IF( _xlpm.対象<>"対象", "", MIN( _xlpm.重複終了上限, _xlpm.換算期間終了 ) ) ) ) -> 48029 | P5: =_xlfn.LET( _xlpm.重複開始,N5, _xlpm.重複終了,O5, IF( G5="同年受取", "", IF( OR(_xlpm.重複開始="",_xlpm.重複終了="",_xlpm.重複開始>_xlpm.重複終了), 0, DATEDIF(_xlpm.重複開始,_xlpm.重複終了+1,"Y") ) ) ) -> 9 | Q5: =IF(G5="同年受取","", _xlfn.LET( _xlpm.受取順,G5, _xlpm.実重複年,P5, _xlpm.会社本来控除,入力!$B$20, _xlpm.重複控除,IF( _xlpm.実重複年<=20, MAX(800000,400000*_xlpm.実重複年), 8000000+700000*(_xlpm.実重複年-20) ), IF( _xlpm.受取順="DC → 会社退職金", IF( I5="対象", MAX(0,_xlpm.会社本来控除-_xlpm.重複控除), _xlpm.会社本来控除 ), _xlpm.会社本来控除 ) )) -> 23300000 | R5: =IF(G5="同年受取","", _xlfn.LET( _xlpm.受取順,G5, _xlpm.DC開始,入力!$B$10, _xlpm.DC終了,B5, _xlpm.実重複年,P5, _xlpm.DC年数,IF( DATEDIF(_xlpm.DC開始,_xlpm.DC終了+1,"M")=0, 1, CEILING(DATEDIF(_xlpm.DC開始,_xlpm.DC終了+1,"M")/12,1) ), _xlpm.DC本来控除,IF( _xlpm.DC年数<=20, 400000*_xlpm.DC年数, 8000000+700000*(_xlpm.DC年数-20) ), _xlpm.重複控除,IF( _xlpm.実重複年=0, 0, IF( _xlpm.実重複年<=20, 400000*_xlpm.実重複年, 8000000+700000*(_xlpm.実重複年-20) ) ), IF( _xlpm.受取順="会社退職金 → DC", IF( I5="対象", MAX(0,_xlpm.DC本来控除-_xlpm.重複控除), _xlpm.DC本来控除 ), _xlpm.DC本来控除 ) ) ) -> 4000000 | S5: =IF(G5="同年受取","",IF(OR(G5="",G5="同日受取：要確認"),"",ROUNDDOWN(MAX(0,(F5-Q5)/2),-3))) -> 0 | T5: =IF(G5="同年受取","",IF(OR(G5="",G5="同日受取：要確認"),"",ROUNDDOWN(MAX(0,(E5-R5)/2),-3))) -> 3000000 | U5: =IF(OR(G5="同年受取",S5=""),"",VLOOKUP(S5,税率表!$A$2:$C$8,2,TRUE)) -> 0.05 | V5: =IF(U5="","",VLOOKUP(S5,税率表!$A$2:$C$8,3,TRUE)) -> 0 | W5: =IF(U5="","",ROUNDDOWN(MAX(0,S5*U5-V5)*1.021,0)) -> 0 | X5: =IF(OR(G5="同年受取",T5=""),"",VLOOKUP(T5,税率表!$A$2:$C$8,2,TRUE)) -> 0.1 | Y5: =IF(X5="","",VLOOKUP(T5,税率表!$A$2:$C$8,3,TRUE)) -> 97500 | Z5: =IF(X5="","",ROUNDDOWN(MAX(0,T5*X5-Y5)*1.021,0)) -> 206752 | AA5: =IF(G5="同年受取","",IF(S5="","",ROUNDDOWN(S5*10%,0))) -> 0 | AB5: =IF(G5="同年受取","",IF(T5="","",ROUNDDOWN(T5*10%,0))) -> 300000 | AC5: =IF(G5="同年受取","",IF(OR(W5="",Z5=""),"",SUM(W5,Z5,AA5,AB5))) -> 506752 | AD5: =IF(G5="同年受取","",IF(AC5="","",E5+F5-AC5)) -> 10493248 | AE5: =IF(G5="同年受取","No.2735：同年の退職手当等を合算し、2制度の勤続期間を統合して退職所得控除額を計算",IF(I5="対象","No.2732：確認期間→前の金額/控除→換算年数→重複年度→後の控除調整→課税退職所得→税額",IF(G5="","",IF(I5="対象外","No.2732：確認期間外→重複調整なし→通常控除→課税退職所得→税額","")))) -> No.2732：確認期間→前の金額/控除→換算年数→重複年度→後の控除調整→課税退職所得→税額 | AF5: =IF(OR(J5="",K5="",G5="同年受取"),"",ROUNDDOWN(IF(J5<=8000000,J5/400000,(J5-8000000)/700000+20),0)) -> 22 | AG5: =IF(OR(J5="",K5="",G5="同年受取"),"",IF(J5<K5,AF5,IF(G5="DC → 会社退職金",入力!$B$21,入力!$B$19))) -> 15 | AH5: =IF(G5<>"同年受取","",_xlfn.LET( _xlpm.A開始,入力!$B$6, _xlpm.A終了,入力!$B$7, _xlpm.B開始,入力!$B$10, _xlpm.B終了,B5, _xlpm.A日数,_xlpm.A終了-_xlpm.A開始+1, _xlpm.B日数,_xlpm.B終了-_xlpm.B開始+1, IF( OR(_xlpm.A終了<_xlpm.B開始,_xlpm.B終了<_xlpm.A開始), IF(_xlpm.A日数>=_xlpm.B日数, DATEDIF(_xlpm.A開始,_xlpm.A終了+1,"Y")+IF(DATEDIF(_xlpm.A開始,_xlpm.A終了+1,"YD")>0,1,0), DATEDIF(_xlpm.B開始,_xlpm.B終了+1,"Y")+IF(DATEDIF(_xlpm.B開始,_xlpm.B終了+1,"YD")>0,1,0) ), DATEDIF(MIN(_xlpm.A開始,_xlpm.B開始),MAX(_xlpm.A終了,_xlpm.B終了)+1,"Y") +IF(DATEDIF(MIN(_xlpm.A開始,_xlpm.B開始),MAX(_xlpm.A終了,_xlpm.B終了)+1,"YD")>0,1,0) ) )) | AI5: =IF(G5<>"同年受取","",IF(AH5<=20,MAX(400000*AH5,800000),8000000+700000*(AH5-20))) | AJ5: =IF(G5<>"同年受取","",MAX(0,FLOOR((E5+F5-AI5)/2,1000))) | AK5: =IF(G5<>"同年受取","",VLOOKUP(AJ5,tabletax,3,TRUE)) | AL5: =IF(G5<>"同年受取","",VLOOKUP(AJ5,tabletax,4,TRUE)) | AM5: =IF(G5<>"同年受取","",FLOOR((AJ5*AK5-AL5)*1.021,1)) | AN5: =IF(G5<>"同年受取","",FLOOR(AJ5*0.1,100)) | AO5: =IF(G5<>"同年受取","",AM5+AN5) | AP5: =IF(G5<>"同年受取","",IF(AM5="","",E5+F5-AO5)) | AQ5: =IF(AD5<>"",AD5,IF(AP5<>"",AP5)) -> 10493248
A6: 3 | B6: 48395 | C6: 48395 | D6: =入力!$B$8 -> 49459 | E6: =入力!$B$13 -> 10000000 | F6: =入力!$B$9 -> 1000000 | G6: =IF(OR(C6="",D6=""),"",IF(YEAR(C6)=YEAR(D6),"同年受取",IF(C6<D6,"DC → 会社退職金","会社退職金 → DC"))) -> DC → 会社退職金 | H6: =IF(OR(G6="同年受取",G6=""),"",IF(G6="DC → 会社退職金",9,19)) -> 9 | I6: =IF(G6="同年受取","同年合算",IF(G6="","",IF(AND(MIN(C6,D6)<DATE(YEAR(MAX(C6,D6)),1,1),MIN(C6,D6)>=DATE(YEAR(MAX(C6,D6))-H6,1,1)),"対象","対象外"))) -> 対象 | J6: =IF(G6="同年受取","",IF(G6="DC → 会社退職金",E6,IF(G6="会社退職金 → DC",F6,""))) -> 10000000 | K6: =IF(G6="同年受取","", IF(G6="DC → 会社退職金", _xlfn.LET( _xlpm.DC開始,入力!$B$10, _xlpm.DC終了,B6, _xlpm.年数,IF(DATEDIF(_xlpm.DC開始,_xlpm.DC終了+1,"M")=0,1,CEILING(DATEDIF(_xlpm.DC開始,_xlpm.DC終了+1,"M")/12,1)), IF(_xlpm.年数<=20,MAX(400000*_xlpm.年数,800000),8000000+700000*(_xlpm.年数-20)) ), IF(G6="会社退職金 → DC", _xlfn.LET( _xlpm.会社控除額,入力!$B$20, _xlpm.会社控除額 ), ""))) -> 4400000 | L6: =IF(OR(J6="",K6=""),"",IF(J6<K6,"該当","非該当")) -> 非該当 | M6: =_xlfn.LET( _xlpm.前判定,L6, _xlpm.前退,J6, _xlpm.前控,K6, _xlpm.会勤年,入力!$B$19, IF(G6="同年受取","", IF(OR(_xlpm.前退="",_xlpm.前控=""),"", IF(_xlpm.前判定="該当", ROUNDDOWN(IF(_xlpm.前退<=8000000,_xlpm.前退/400000,(_xlpm.前退-8000000)/700000+20),0), IF(G6="DC → 会社退職金", _xlfn.LET( _xlpm.DC開始,入力!$B$10, _xlpm.DC終了,B6, DATEDIF(_xlpm.DC開始,_xlpm.DC終了+1,"Y") +IF(DATEDIF(_xlpm.DC開始,_xlpm.DC終了+1,"YD")>0,1,0) ), IF(G6="会社退職金 → DC", _xlpm.会勤年, "" ) ) ) ) ) ) -> 11 | N6: =IF(G6="同年受取","",IF(I6<>"対象","",MAX(IF(G6="DC → 会社退職金",入力!$B$10,入力!$B$6),IF(G6="DC → 会社退職金",入力!$B$6,入力!$B$10)))) -> 44652 | O6: =_xlfn.LET( _xlpm.受取順,G6, _xlpm.対象,I6, _xlpm.前退,J6, _xlpm.前控,K6, _xlpm.前換算年,M6, _xlpm.会社開始,入力!$B$6, _xlpm.会社終了,入力!$B$7, _xlpm.DC開始,入力!$B$10, _xlpm.DC終了,B6, _xlpm.重複終了上限,IF( _xlpm.受取順="DC → 会社退職金", _xlpm.DC終了, _xlpm.会社終了 ), _xlpm.換算期間終了,IF( _xlpm.前退<_xlpm.前控, EDATE( IF( _xlpm.受取順="DC → 会社退職金", _xlpm.DC開始, _xlpm.会社開始 ), _xlpm.前換算年*12 )-1, _xlpm.重複終了上限 ), IF( _xlpm.受取順="同年受取", "", IF( _xlpm.対象<>"対象", "", MIN( _xlpm.重複終了上限, _xlpm.換算期間終了 ) ) ) ) -> 48395 | P6: =_xlfn.LET( _xlpm.重複開始,N6, _xlpm.重複終了,O6, IF( G6="同年受取", "", IF( OR(_xlpm.重複開始="",_xlpm.重複終了="",_xlpm.重複開始>_xlpm.重複終了), 0, DATEDIF(_xlpm.重複開始,_xlpm.重複終了+1,"Y") ) ) ) -> 10 | Q6: =IF(G6="同年受取","", _xlfn.LET( _xlpm.受取順,G6, _xlpm.実重複年,P6, _xlpm.会社本来控除,入力!$B$20, _xlpm.重複控除,IF( _xlpm.実重複年<=20, MAX(800000,400000*_xlpm.実重複年), 8000000+700000*(_xlpm.実重複年-20) ), IF( _xlpm.受取順="DC → 会社退職金", IF( I6="対象", MAX(0,_xlpm.会社本来控除-_xlpm.重複控除), _xlpm.会社本来控除 ), _xlpm.会社本来控除 ) )) -> 22900000 | R6: =IF(G6="同年受取","", _xlfn.LET( _xlpm.受取順,G6, _xlpm.DC開始,入力!$B$10, _xlpm.DC終了,B6, _xlpm.実重複年,P6, _xlpm.DC年数,IF( DATEDIF(_xlpm.DC開始,_xlpm.DC終了+1,"M")=0, 1, CEILING(DATEDIF(_xlpm.DC開始,_xlpm.DC終了+1,"M")/12,1) ), _xlpm.DC本来控除,IF( _xlpm.DC年数<=20, 400000*_xlpm.DC年数, 8000000+700000*(_xlpm.DC年数-20) ), _xlpm.重複控除,IF( _xlpm.実重複年=0, 0, IF( _xlpm.実重複年<=20, 400000*_xlpm.実重複年, 8000000+700000*(_xlpm.実重複年-20) ) ), IF( _xlpm.受取順="会社退職金 → DC", IF( I6="対象", MAX(0,_xlpm.DC本来控除-_xlpm.重複控除), _xlpm.DC本来控除 ), _xlpm.DC本来控除 ) ) ) -> 4400000 | S6: =IF(G6="同年受取","",IF(OR(G6="",G6="同日受取：要確認"),"",ROUNDDOWN(MAX(0,(F6-Q6)/2),-3))) -> 0 | T6: =IF(G6="同年受取","",IF(OR(G6="",G6="同日受取：要確認"),"",ROUNDDOWN(MAX(0,(E6-R6)/2),-3))) -> 2800000 | U6: =IF(OR(G6="同年受取",S6=""),"",VLOOKUP(S6,税率表!$A$2:$C$8,2,TRUE)) -> 0.05 | V6: =IF(U6="","",VLOOKUP(S6,税率表!$A$2:$C$8,3,TRUE)) -> 0 | W6: =IF(U6="","",ROUNDDOWN(MAX(0,S6*U6-V6)*1.021,0)) -> 0 | X6: =IF(OR(G6="同年受取",T6=""),"",VLOOKUP(T6,税率表!$A$2:$C$8,2,TRUE)) -> 0.1 | Y6: =IF(X6="","",VLOOKUP(T6,税率表!$A$2:$C$8,3,TRUE)) -> 97500 | Z6: =IF(X6="","",ROUNDDOWN(MAX(0,T6*X6-Y6)*1.021,0)) -> 186332 | AA6: =IF(G6="同年受取","",IF(S6="","",ROUNDDOWN(S6*10%,0))) -> 0 | AB6: =IF(G6="同年受取","",IF(T6="","",ROUNDDOWN(T6*10%,0))) -> 280000 | AC6: =IF(G6="同年受取","",IF(OR(W6="",Z6=""),"",SUM(W6,Z6,AA6,AB6))) -> 466332 | AD6: =IF(G6="同年受取","",IF(AC6="","",E6+F6-AC6)) -> 10533668 | AE6: =IF(G6="同年受取","No.2735：同年の退職手当等を合算し、2制度の勤続期間を統合して退職所得控除額を計算",IF(I6="対象","No.2732：確認期間→前の金額/控除→換算年数→重複年度→後の控除調整→課税退職所得→税額",IF(G6="","",IF(I6="対象外","No.2732：確認期間外→重複調整なし→通常控除→課税退職所得→税額","")))) -> No.2732：確認期間→前の金額/控除→換算年数→重複年度→後の控除調整→課税退職所得→税額 | AF6: =IF(OR(J6="",K6="",G6="同年受取"),"",ROUNDDOWN(IF(J6<=8000000,J6/400000,(J6-8000000)/700000+20),0)) -> 22 | AG6: =IF(OR(J6="",K6="",G6="同年受取"),"",IF(J6<K6,AF6,IF(G6="DC → 会社退職金",入力!$B$21,入力!$B$19))) -> 15 | AH6: =IF(G6<>"同年受取","",_xlfn.LET( _xlpm.A開始,入力!$B$6, _xlpm.A終了,入力!$B$7, _xlpm.B開始,入力!$B$10, _xlpm.B終了,B6, _xlpm.A日数,_xlpm.A終了-_xlpm.A開始+1, _xlpm.B日数,_xlpm.B終了-_xlpm.B開始+1, IF( OR(_xlpm.A終了<_xlpm.B開始,_xlpm.B終了<_xlpm.A開始), IF(_xlpm.A日数>=_xlpm.B日数, DATEDIF(_xlpm.A開始,_xlpm.A終了+1,"Y")+IF(DATEDIF(_xlpm.A開始,_xlpm.A終了+1,"YD")>0,1,0), DATEDIF(_xlpm.B開始,_xlpm.B終了+1,"Y")+IF(DATEDIF(_xlpm.B開始,_xlpm.B終了+1,"YD")>0,1,0) ), DATEDIF(MIN(_xlpm.A開始,_xlpm.B開始),MAX(_xlpm.A終了,_xlpm.B終了)+1,"Y") +IF(DATEDIF(MIN(_xlpm.A開始,_xlpm.B開始),MAX(_xlpm.A終了,_xlpm.B終了)+1,"YD")>0,1,0) ) )) | AI6: =IF(G6<>"同年受取","",IF(AH6<=20,MAX(400000*AH6,800000),8000000+700000*(AH6-20))) | AJ6: =IF(G6<>"同年受取","",MAX(0,FLOOR((E6+F6-AI6)/2,1000))) | AK6: =IF(G6<>"同年受取","",VLOOKUP(AJ6,tabletax,3,TRUE)) | AL6: =IF(G6<>"同年受取","",VLOOKUP(AJ6,tabletax,4,TRUE)) | AM6: =IF(G6<>"同年受取","",FLOOR((AJ6*AK6-AL6)*1.021,1)) | AN6: =IF(G6<>"同年受取","",FLOOR(AJ6*0.1,100)) | AO6: =IF(G6<>"同年受取","",AM6+AN6) | AP6: =IF(G6<>"同年受取","",IF(AM6="","",E6+F6-AO6)) | AQ6: =IF(AD6<>"",AD6,IF(AP6<>"",AP6)) -> 10533668
A7: 4 | B7: 48760 | C7: 48760 | D7: =入力!$B$8 -> 49459 | E7: =入力!$B$13 -> 10000000 | F7: =入力!$B$9 -> 1000000 | G7: =IF(OR(C7="",D7=""),"",IF(YEAR(C7)=YEAR(D7),"同年受取",IF(C7<D7,"DC → 会社退職金","会社退職金 → DC"))) -> DC → 会社退職金 | H7: =IF(OR(G7="同年受取",G7=""),"",IF(G7="DC → 会社退職金",9,19)) -> 9 | I7: =IF(G7="同年受取","同年合算",IF(G7="","",IF(AND(MIN(C7,D7)<DATE(YEAR(MAX(C7,D7)),1,1),MIN(C7,D7)>=DATE(YEAR(MAX(C7,D7))-H7,1,1)),"対象","対象外"))) -> 対象 | J7: =IF(G7="同年受取","",IF(G7="DC → 会社退職金",E7,IF(G7="会社退職金 → DC",F7,""))) -> 10000000 | K7: =IF(G7="同年受取","", IF(G7="DC → 会社退職金", _xlfn.LET( _xlpm.DC開始,入力!$B$10, _xlpm.DC終了,B7, _xlpm.年数,IF(DATEDIF(_xlpm.DC開始,_xlpm.DC終了+1,"M")=0,1,CEILING(DATEDIF(_xlpm.DC開始,_xlpm.DC終了+1,"M")/12,1)), IF(_xlpm.年数<=20,MAX(400000*_xlpm.年数,800000),8000000+700000*(_xlpm.年数-20)) ), IF(G7="会社退職金 → DC", _xlfn.LET( _xlpm.会社控除額,入力!$B$20, _xlpm.会社控除額 ), ""))) -> 4800000 | L7: =IF(OR(J7="",K7=""),"",IF(J7<K7,"該当","非該当")) -> 非該当 | M7: =_xlfn.LET( _xlpm.前判定,L7, _xlpm.前退,J7, _xlpm.前控,K7, _xlpm.会勤年,入力!$B$19, IF(G7="同年受取","", IF(OR(_xlpm.前退="",_xlpm.前控=""),"", IF(_xlpm.前判定="該当", ROUNDDOWN(IF(_xlpm.前退<=8000000,_xlpm.前退/400000,(_xlpm.前退-8000000)/700000+20),0), IF(G7="DC → 会社退職金", _xlfn.LET( _xlpm.DC開始,入力!$B$10, _xlpm.DC終了,B7, DATEDIF(_xlpm.DC開始,_xlpm.DC終了+1,"Y") +IF(DATEDIF(_xlpm.DC開始,_xlpm.DC終了+1,"YD")>0,1,0) ), IF(G7="会社退職金 → DC", _xlpm.会勤年, "" ) ) ) ) ) ) -> 12 | N7: =IF(G7="同年受取","",IF(I7<>"対象","",MAX(IF(G7="DC → 会社退職金",入力!$B$10,入力!$B$6),IF(G7="DC → 会社退職金",入力!$B$6,入力!$B$10)))) -> 44652 | O7: =_xlfn.LET( _xlpm.受取順,G7, _xlpm.対象,I7, _xlpm.前退,J7, _xlpm.前控,K7, _xlpm.前換算年,M7, _xlpm.会社開始,入力!$B$6, _xlpm.会社終了,入力!$B$7, _xlpm.DC開始,入力!$B$10, _xlpm.DC終了,B7, _xlpm.重複終了上限,IF( _xlpm.受取順="DC → 会社退職金", _xlpm.DC終了, _xlpm.会社終了 ), _xlpm.換算期間終了,IF( _xlpm.前退<_xlpm.前控, EDATE( IF( _xlpm.受取順="DC → 会社退職金", _xlpm.DC開始, _xlpm.会社開始 ), _xlpm.前換算年*12 )-1, _xlpm.重複終了上限 ), IF( _xlpm.受取順="同年受取", "", IF( _xlpm.対象<>"対象", "", MIN( _xlpm.重複終了上限, _xlpm.換算期間終了 ) ) ) ) -> 48760 | P7: =_xlfn.LET( _xlpm.重複開始,N7, _xlpm.重複終了,O7, IF( G7="同年受取", "", IF( OR(_xlpm.重複開始="",_xlpm.重複終了="",_xlpm.重複開始>_xlpm.重複終了), 0, DATEDIF(_xlpm.重複開始,_xlpm.重複終了+1,"Y") ) ) ) -> 11 | Q7: =IF(G7="同年受取","", _xlfn.LET( _xlpm.受取順,G7, _xlpm.実重複年,P7, _xlpm.会社本来控除,入力!$B$20, _xlpm.重複控除,IF( _xlpm.実重複年<=20, MAX(800000,400000*_xlpm.実重複年), 8000000+700000*(_xlpm.実重複年-20) ), IF( _xlpm.受取順="DC → 会社退職金", IF( I7="対象", MAX(0,_xlpm.会社本来控除-_xlpm.重複控除), _xlpm.会社本来控除 ), _xlpm.会社本来控除 ) )) -> 22500000 | R7: =IF(G7="同年受取","", _xlfn.LET( _xlpm.受取順,G7, _xlpm.DC開始,入力!$B$10, _xlpm.DC終了,B7, _xlpm.実重複年,P7, _xlpm.DC年数,IF( DATEDIF(_xlpm.DC開始,_xlpm.DC終了+1,"M")=0, 1, CEILING(DATEDIF(_xlpm.DC開始,_xlpm.DC終了+1,"M")/12,1) ), _xlpm.DC本来控除,IF( _xlpm.DC年数<=20, 400000*_xlpm.DC年数, 8000000+700000*(_xlpm.DC年数-20) ), _xlpm.重複控除,IF( _xlpm.実重複年=0, 0, IF( _xlpm.実重複年<=20, 400000*_xlpm.実重複年, 8000000+700000*(_xlpm.実重複年-20) ) ), IF( _xlpm.受取順="会社退職金 → DC", IF( I7="対象", MAX(0,_xlpm.DC本来控除-_xlpm.重複控除), _xlpm.DC本来控除 ), _xlpm.DC本来控除 ) ) ) -> 4800000 | S7: =IF(G7="同年受取","",IF(OR(G7="",G7="同日受取：要確認"),"",ROUNDDOWN(MAX(0,(F7-Q7)/2),-3))) -> 0 | T7: =IF(G7="同年受取","",IF(OR(G7="",G7="同日受取：要確認"),"",ROUNDDOWN(MAX(0,(E7-R7)/2),-3))) -> 2600000 | U7: =IF(OR(G7="同年受取",S7=""),"",VLOOKUP(S7,税率表!$A$2:$C$8,2,TRUE)) -> 0.05 | V7: =IF(U7="","",VLOOKUP(S7,税率表!$A$2:$C$8,3,TRUE)) -> 0 | W7: =IF(U7="","",ROUNDDOWN(MAX(0,S7*U7-V7)*1.021,0)) -> 0 | X7: =IF(OR(G7="同年受取",T7=""),"",VLOOKUP(T7,税率表!$A$2:$C$8,2,TRUE)) -> 0.1 | Y7: =IF(X7="","",VLOOKUP(T7,税率表!$A$2:$C$8,3,TRUE)) -> 97500 | Z7: =IF(X7="","",ROUNDDOWN(MAX(0,T7*X7-Y7)*1.021,0)) -> 165912 | AA7: =IF(G7="同年受取","",IF(S7="","",ROUNDDOWN(S7*10%,0))) -> 0 | AB7: =IF(G7="同年受取","",IF(T7="","",ROUNDDOWN(T7*10%,0))) -> 260000 | AC7: =IF(G7="同年受取","",IF(OR(W7="",Z7=""),"",SUM(W7,Z7,AA7,AB7))) -> 425912 | AD7: =IF(G7="同年受取","",IF(AC7="","",E7+F7-AC7)) -> 10574088 | AE7: =IF(G7="同年受取","No.2735：同年の退職手当等を合算し、2制度の勤続期間を統合して退職所得控除額を計算",IF(I7="対象","No.2732：確認期間→前の金額/控除→換算年数→重複年度→後の控除調整→課税退職所得→税額",IF(G7="","",IF(I7="対象外","No.2732：確認期間外→重複調整なし→通常控除→課税退職所得→税額","")))) -> No.2732：確認期間→前の金額/控除→換算年数→重複年度→後の控除調整→課税退職所得→税額 | AF7: =IF(OR(J7="",K7="",G7="同年受取"),"",ROUNDDOWN(IF(J7<=8000000,J7/400000,(J7-8000000)/700000+20),0)) -> 22 | AG7: =IF(OR(J7="",K7="",G7="同年受取"),"",IF(J7<K7,AF7,IF(G7="DC → 会社退職金",入力!$B$21,入力!$B$19))) -> 15 | AH7: =IF(G7<>"同年受取","",_xlfn.LET( _xlpm.A開始,入力!$B$6, _xlpm.A終了,入力!$B$7, _xlpm.B開始,入力!$B$10, _xlpm.B終了,B7, _xlpm.A日数,_xlpm.A終了-_xlpm.A開始+1, _xlpm.B日数,_xlpm.B終了-_xlpm.B開始+1, IF( OR(_xlpm.A終了<_xlpm.B開始,_xlpm.B終了<_xlpm.A開始), IF(_xlpm.A日数>=_xlpm.B日数, DATEDIF(_xlpm.A開始,_xlpm.A終了+1,"Y")+IF(DATEDIF(_xlpm.A開始,_xlpm.A終了+1,"YD")>0,1,0), DATEDIF(_xlpm.B開始,_xlpm.B終了+1,"Y")+IF(DATEDIF(_xlpm.B開始,_xlpm.B終了+1,"YD")>0,1,0) ), DATEDIF(MIN(_xlpm.A開始,_xlpm.B開始),MAX(_xlpm.A終了,_xlpm.B終了)+1,"Y") +IF(DATEDIF(MIN(_xlpm.A開始,_xlpm.B開始),MAX(_xlpm.A終了,_xlpm.B終了)+1,"YD")>0,1,0) ) )) | AI7: =IF(G7<>"同年受取","",IF(AH7<=20,MAX(400000*AH7,800000),8000000+700000*(AH7-20))) | AJ7: =IF(G7<>"同年受取","",MAX(0,FLOOR((E7+F7-AI7)/2,1000))) | AK7: =IF(G7<>"同年受取","",VLOOKUP(AJ7,tabletax,3,TRUE)) | AL7: =IF(G7<>"同年受取","",VLOOKUP(AJ7,tabletax,4,TRUE)) | AM7: =IF(G7<>"同年受取","",FLOOR((AJ7*AK7-AL7)*1.021,1)) | AN7: =IF(G7<>"同年受取","",FLOOR(AJ7*0.1,100)) | AO7: =IF(G7<>"同年受取","",AM7+AN7) | AP7: =IF(G7<>"同年受取","",IF(AM7="","",E7+F7-AO7)) | AQ7: =IF(AD7<>"",AD7,IF(AP7<>"",AP7)) -> 10574088
A8: 5 | B8: 49125 | C8: 49125 | D8: =入力!$B$8 -> 49459 | E8: =入力!$B$13 -> 10000000 | F8: =入力!$B$9 -> 1000000 | G8: =IF(OR(C8="",D8=""),"",IF(YEAR(C8)=YEAR(D8),"同年受取",IF(C8<D8,"DC → 会社退職金","会社退職金 → DC"))) -> DC → 会社退職金 | H8: =IF(OR(G8="同年受取",G8=""),"",IF(G8="DC → 会社退職金",9,19)) -> 9 | I8: =IF(G8="同年受取","同年合算",IF(G8="","",IF(AND(MIN(C8,D8)<DATE(YEAR(MAX(C8,D8)),1,1),MIN(C8,D8)>=DATE(YEAR(MAX(C8,D8))-H8,1,1)),"対象","対象外"))) -> 対象 | J8: =IF(G8="同年受取","",IF(G8="DC → 会社退職金",E8,IF(G8="会社退職金 → DC",F8,""))) -> 10000000 | K8: =IF(G8="同年受取","", IF(G8="DC → 会社退職金", _xlfn.LET( _xlpm.DC開始,入力!$B$10, _xlpm.DC終了,B8, _xlpm.年数,IF(DATEDIF(_xlpm.DC開始,_xlpm.DC終了+1,"M")=0,1,CEILING(DATEDIF(_xlpm.DC開始,_xlpm.DC終了+1,"M")/12,1)), IF(_xlpm.年数<=20,MAX(400000*_xlpm.年数,800000),8000000+700000*(_xlpm.年数-20)) ), IF(G8="会社退職金 → DC", _xlfn.LET( _xlpm.会社控除額,入力!$B$20, _xlpm.会社控除額 ), ""))) -> 5200000 | L8: =IF(OR(J8="",K8=""),"",IF(J8<K8,"該当","非該当")) -> 非該当 | M8: =_xlfn.LET( _xlpm.前判定,L8, _xlpm.前退,J8, _xlpm.前控,K8, _xlpm.会勤年,入力!$B$19, IF(G8="同年受取","", IF(OR(_xlpm.前退="",_xlpm.前控=""),"", IF(_xlpm.前判定="該当", ROUNDDOWN(IF(_xlpm.前退<=8000000,_xlpm.前退/400000,(_xlpm.前退-8000000)/700000+20),0), IF(G8="DC → 会社退職金", _xlfn.LET( _xlpm.DC開始,入力!$B$10, _xlpm.DC終了,B8, DATEDIF(_xlpm.DC開始,_xlpm.DC終了+1,"Y") +IF(DATEDIF(_xlpm.DC開始,_xlpm.DC終了+1,"YD")>0,1,0) ), IF(G8="会社退職金 → DC", _xlpm.会勤年, "" ) ) ) ) ) ) -> 13 | N8: =IF(G8="同年受取","",IF(I8<>"対象","",MAX(IF(G8="DC → 会社退職金",入力!$B$10,入力!$B$6),IF(G8="DC → 会社退職金",入力!$B$6,入力!$B$10)))) -> 44652 | O8: =_xlfn.LET( _xlpm.受取順,G8, _xlpm.対象,I8, _xlpm.前退,J8, _xlpm.前控,K8, _xlpm.前換算年,M8, _xlpm.会社開始,入力!$B$6, _xlpm.会社終了,入力!$B$7, _xlpm.DC開始,入力!$B$10, _xlpm.DC終了,B8, _xlpm.重複終了上限,IF( _xlpm.受取順="DC → 会社退職金", _xlpm.DC終了, _xlpm.会社終了 ), _xlpm.換算期間終了,IF( _xlpm.前退<_xlpm.前控, EDATE( IF( _xlpm.受取順="DC → 会社退職金", _xlpm.DC開始, _xlpm.会社開始 ), _xlpm.前換算年*12 )-1, _xlpm.重複終了上限 ), IF( _xlpm.受取順="同年受取", "", IF( _xlpm.対象<>"対象", "", MIN( _xlpm.重複終了上限, _xlpm.換算期間終了 ) ) ) ) -> 49125 | P8: =_xlfn.LET( _xlpm.重複開始,N8, _xlpm.重複終了,O8, IF( G8="同年受取", "", IF( OR(_xlpm.重複開始="",_xlpm.重複終了="",_xlpm.重複開始>_xlpm.重複終了), 0, DATEDIF(_xlpm.重複開始,_xlpm.重複終了+1,"Y") ) ) ) -> 12 | Q8: =IF(G8="同年受取","", _xlfn.LET( _xlpm.受取順,G8, _xlpm.実重複年,P8, _xlpm.会社本来控除,入力!$B$20, _xlpm.重複控除,IF( _xlpm.実重複年<=20, MAX(800000,400000*_xlpm.実重複年), 8000000+700000*(_xlpm.実重複年-20) ), IF( _xlpm.受取順="DC → 会社退職金", IF( I8="対象", MAX(0,_xlpm.会社本来控除-_xlpm.重複控除), _xlpm.会社本来控除 ), _xlpm.会社本来控除 ) )) -> 22100000 | R8: =IF(G8="同年受取","", _xlfn.LET( _xlpm.受取順,G8, _xlpm.DC開始,入力!$B$10, _xlpm.DC終了,B8, _xlpm.実重複年,P8, _xlpm.DC年数,IF( DATEDIF(_xlpm.DC開始,_xlpm.DC終了+1,"M")=0, 1, CEILING(DATEDIF(_xlpm.DC開始,_xlpm.DC終了+1,"M")/12,1) ), _xlpm.DC本来控除,IF( _xlpm.DC年数<=20, 400000*_xlpm.DC年数, 8000000+700000*(_xlpm.DC年数-20) ), _xlpm.重複控除,IF( _xlpm.実重複年=0, 0, IF( _xlpm.実重複年<=20, 400000*_xlpm.実重複年, 8000000+700000*(_xlpm.実重複年-20) ) ), IF( _xlpm.受取順="会社退職金 → DC", IF( I8="対象", MAX(0,_xlpm.DC本来控除-_xlpm.重複控除), _xlpm.DC本来控除 ), _xlpm.DC本来控除 ) ) ) -> 5200000 | S8: =IF(G8="同年受取","",IF(OR(G8="",G8="同日受取：要確認"),"",ROUNDDOWN(MAX(0,(F8-Q8)/2),-3))) -> 0 | T8: =IF(G8="同年受取","",IF(OR(G8="",G8="同日受取：要確認"),"",ROUNDDOWN(MAX(0,(E8-R8)/2),-3))) -> 2400000 | U8: =IF(OR(G8="同年受取",S8=""),"",VLOOKUP(S8,税率表!$A$2:$C$8,2,TRUE)) -> 0.05 | V8: =IF(U8="","",VLOOKUP(S8,税率表!$A$2:$C$8,3,TRUE)) -> 0 | W8: =IF(U8="","",ROUNDDOWN(MAX(0,S8*U8-V8)*1.021,0)) -> 0 | X8: =IF(OR(G8="同年受取",T8=""),"",VLOOKUP(T8,税率表!$A$2:$C$8,2,TRUE)) -> 0.1 | Y8: =IF(X8="","",VLOOKUP(T8,税率表!$A$2:$C$8,3,TRUE)) -> 97500 | Z8: =IF(X8="","",ROUNDDOWN(MAX(0,T8*X8-Y8)*1.021,0)) -> 145492 | AA8: =IF(G8="同年受取","",IF(S8="","",ROUNDDOWN(S8*10%,0))) -> 0 | AB8: =IF(G8="同年受取","",IF(T8="","",ROUNDDOWN(T8*10%,0))) -> 240000 | AC8: =IF(G8="同年受取","",IF(OR(W8="",Z8=""),"",SUM(W8,Z8,AA8,AB8))) -> 385492 | AD8: =IF(G8="同年受取","",IF(AC8="","",E8+F8-AC8)) -> 10614508 | AE8: =IF(G8="同年受取","No.2735：同年の退職手当等を合算し、2制度の勤続期間を統合して退職所得控除額を計算",IF(I8="対象","No.2732：確認期間→前の金額/控除→換算年数→重複年度→後の控除調整→課税退職所得→税額",IF(G8="","",IF(I8="対象外","No.2732：確認期間外→重複調整なし→通常控除→課税退職所得→税額","")))) -> No.2732：確認期間→前の金額/控除→換算年数→重複年度→後の控除調整→課税退職所得→税額 | AF8: =IF(OR(J8="",K8="",G8="同年受取"),"",ROUNDDOWN(IF(J8<=8000000,J8/400000,(J8-8000000)/700000+20),0)) -> 22 | AG8: =IF(OR(J8="",K8="",G8="同年受取"),"",IF(J8<K8,AF8,IF(G8="DC → 会社退職金",入力!$B$21,入力!$B$19))) -> 15 | AH8: =IF(G8<>"同年受取","",_xlfn.LET( _xlpm.A開始,入力!$B$6, _xlpm.A終了,入力!$B$7, _xlpm.B開始,入力!$B$10, _xlpm.B終了,B8, _xlpm.A日数,_xlpm.A終了-_xlpm.A開始+1, _xlpm.B日数,_xlpm.B終了-_xlpm.B開始+1, IF( OR(_xlpm.A終了<_xlpm.B開始,_xlpm.B終了<_xlpm.A開始), IF(_xlpm.A日数>=_xlpm.B日数, DATEDIF(_xlpm.A開始,_xlpm.A終了+1,"Y")+IF(DATEDIF(_xlpm.A開始,_xlpm.A終了+1,"YD")>0,1,0), DATEDIF(_xlpm.B開始,_xlpm.B終了+1,"Y")+IF(DATEDIF(_xlpm.B開始,_xlpm.B終了+1,"YD")>0,1,0) ), DATEDIF(MIN(_xlpm.A開始,_xlpm.B開始),MAX(_xlpm.A終了,_xlpm.B終了)+1,"Y") +IF(DATEDIF(MIN(_xlpm.A開始,_xlpm.B開始),MAX(_xlpm.A終了,_xlpm.B終了)+1,"YD")>0,1,0) ) )) | AI8: =IF(G8<>"同年受取","",IF(AH8<=20,MAX(400000*AH8,800000),8000000+700000*(AH8-20))) | AJ8: =IF(G8<>"同年受取","",MAX(0,FLOOR((E8+F8-AI8)/2,1000))) | AK8: =IF(G8<>"同年受取","",VLOOKUP(AJ8,tabletax,3,TRUE)) | AL8: =IF(G8<>"同年受取","",VLOOKUP(AJ8,tabletax,4,TRUE)) | AM8: =IF(G8<>"同年受取","",FLOOR((AJ8*AK8-AL8)*1.021,1)) | AN8: =IF(G8<>"同年受取","",FLOOR(AJ8*0.1,100)) | AO8: =IF(G8<>"同年受取","",AM8+AN8) | AP8: =IF(G8<>"同年受取","",IF(AM8="","",E8+F8-AO8)) | AQ8: =IF(AD8<>"",AD8,IF(AP8<>"",AP8)) -> 10614508
A9: 6 | B9: 49490 | C9: 49490 | D9: =入力!$B$8 -> 49459 | E9: =入力!$B$13 -> 10000000 | F9: =入力!$B$9 -> 1000000 | G9: =IF(OR(C9="",D9=""),"",IF(YEAR(C9)=YEAR(D9),"同年受取",IF(C9<D9,"DC → 会社退職金","会社退職金 → DC"))) -> 同年受取 | H9: =IF(OR(G9="同年受取",G9=""),"",IF(G9="DC → 会社退職金",9,19)) | I9: =IF(G9="同年受取","同年合算",IF(G9="","",IF(AND(MIN(C9,D9)<DATE(YEAR(MAX(C9,D9)),1,1),MIN(C9,D9)>=DATE(YEAR(MAX(C9,D9))-H9,1,1)),"対象","対象外"))) -> 同年合算 | J9: =IF(G9="同年受取","",IF(G9="DC → 会社退職金",E9,IF(G9="会社退職金 → DC",F9,""))) | K9: =IF(G9="同年受取","", IF(G9="DC → 会社退職金", _xlfn.LET( _xlpm.DC開始,入力!$B$10, _xlpm.DC終了,B9, _xlpm.年数,IF(DATEDIF(_xlpm.DC開始,_xlpm.DC終了+1,"M")=0,1,CEILING(DATEDIF(_xlpm.DC開始,_xlpm.DC終了+1,"M")/12,1)), IF(_xlpm.年数<=20,MAX(400000*_xlpm.年数,800000),8000000+700000*(_xlpm.年数-20)) ), IF(G9="会社退職金 → DC", _xlfn.LET( _xlpm.会社控除額,入力!$B$20, _xlpm.会社控除額 ), ""))) | L9: =IF(OR(J9="",K9=""),"",IF(J9<K9,"該当","非該当")) | M9: =_xlfn.LET( _xlpm.前判定,L9, _xlpm.前退,J9, _xlpm.前控,K9, _xlpm.会勤年,入力!$B$19, IF(G9="同年受取","", IF(OR(_xlpm.前退="",_xlpm.前控=""),"", IF(_xlpm.前判定="該当", ROUNDDOWN(IF(_xlpm.前退<=8000000,_xlpm.前退/400000,(_xlpm.前退-8000000)/700000+20),0), IF(G9="DC → 会社退職金", _xlfn.LET( _xlpm.DC開始,入力!$B$10, _xlpm.DC終了,B9, DATEDIF(_xlpm.DC開始,_xlpm.DC終了+1,"Y") +IF(DATEDIF(_xlpm.DC開始,_xlpm.DC終了+1,"YD")>0,1,0) ), IF(G9="会社退職金 → DC", _xlpm.会勤年, "" ) ) ) ) ) ) | N9: =IF(G9="同年受取","",IF(I9<>"対象","",MAX(IF(G9="DC → 会社退職金",入力!$B$10,入力!$B$6),IF(G9="DC → 会社退職金",入力!$B$6,入力!$B$10)))) | O9: =_xlfn.LET( _xlpm.受取順,G9, _xlpm.対象,I9, _xlpm.前退,J9, _xlpm.前控,K9, _xlpm.前換算年,M9, _xlpm.会社開始,入力!$B$6, _xlpm.会社終了,入力!$B$7, _xlpm.DC開始,入力!$B$10, _xlpm.DC終了,B9, _xlpm.重複終了上限,IF( _xlpm.受取順="DC → 会社退職金", _xlpm.DC終了, _xlpm.会社終了 ), _xlpm.換算期間終了,IF( _xlpm.前退<_xlpm.前控, EDATE( IF( _xlpm.受取順="DC → 会社退職金", _xlpm.DC開始, _xlpm.会社開始 ), _xlpm.前換算年*12 )-1, _xlpm.重複終了上限 ), IF( _xlpm.受取順="同年受取", "", IF( _xlpm.対象<>"対象", "", MIN( _xlpm.重複終了上限, _xlpm.換算期間終了 ) ) ) ) | P9: =_xlfn.LET( _xlpm.重複開始,N9, _xlpm.重複終了,O9, IF( G9="同年受取", "", IF( OR(_xlpm.重複開始="",_xlpm.重複終了="",_xlpm.重複開始>_xlpm.重複終了), 0, DATEDIF(_xlpm.重複開始,_xlpm.重複終了+1,"Y") ) ) ) | Q9: =IF(G9="同年受取","", _xlfn.LET( _xlpm.受取順,G9, _xlpm.実重複年,P9, _xlpm.会社本来控除,入力!$B$20, _xlpm.重複控除,IF( _xlpm.実重複年<=20, MAX(800000,400000*_xlpm.実重複年), 8000000+700000*(_xlpm.実重複年-20) ), IF( _xlpm.受取順="DC → 会社退職金", IF( I9="対象", MAX(0,_xlpm.会社本来控除-_xlpm.重複控除), _xlpm.会社本来控除 ), _xlpm.会社本来控除 ) )) | R9: =IF(G9="同年受取","", _xlfn.LET( _xlpm.受取順,G9, _xlpm.DC開始,入力!$B$10, _xlpm.DC終了,B9, _xlpm.実重複年,P9, _xlpm.DC年数,IF( DATEDIF(_xlpm.DC開始,_xlpm.DC終了+1,"M")=0, 1, CEILING(DATEDIF(_xlpm.DC開始,_xlpm.DC終了+1,"M")/12,1) ), _xlpm.DC本来控除,IF( _xlpm.DC年数<=20, 400000*_xlpm.DC年数, 8000000+700000*(_xlpm.DC年数-20) ), _xlpm.重複控除,IF( _xlpm.実重複年=0, 0, IF( _xlpm.実重複年<=20, 400000*_xlpm.実重複年, 8000000+700000*(_xlpm.実重複年-20) ) ), IF( _xlpm.受取順="会社退職金 → DC", IF( I9="対象", MAX(0,_xlpm.DC本来控除-_xlpm.重複控除), _xlpm.DC本来控除 ), _xlpm.DC本来控除 ) ) ) | S9: =IF(G9="同年受取","",IF(OR(G9="",G9="同日受取：要確認"),"",ROUNDDOWN(MAX(0,(F9-Q9)/2),-3))) | T9: =IF(G9="同年受取","",IF(OR(G9="",G9="同日受取：要確認"),"",ROUNDDOWN(MAX(0,(E9-R9)/2),-3))) | U9: =IF(OR(G9="同年受取",S9=""),"",VLOOKUP(S9,税率表!$A$2:$C$8,2,TRUE)) | V9: =IF(U9="","",VLOOKUP(S9,税率表!$A$2:$C$8,3,TRUE)) | W9: =IF(U9="","",ROUNDDOWN(MAX(0,S9*U9-V9)*1.021,0)) | X9: =IF(OR(G9="同年受取",T9=""),"",VLOOKUP(T9,税率表!$A$2:$C$8,2,TRUE)) | Y9: =IF(X9="","",VLOOKUP(T9,税率表!$A$2:$C$8,3,TRUE)) | Z9: =IF(X9="","",ROUNDDOWN(MAX(0,T9*X9-Y9)*1.021,0)) | AA9: =IF(G9="同年受取","",IF(S9="","",ROUNDDOWN(S9*10%,0))) | AB9: =IF(G9="同年受取","",IF(T9="","",ROUNDDOWN(T9*10%,0))) | AC9: =IF(G9="同年受取","",IF(OR(W9="",Z9=""),"",SUM(W9,Z9,AA9,AB9))) | AD9: =IF(G9="同年受取","",IF(AC9="","",E9+F9-AC9)) | AE9: =IF(G9="同年受取","No.2735：同年の退職手当等を合算し、2制度の勤続期間を統合して退職所得控除額を計算",IF(I9="対象","No.2732：確認期間→前の金額/控除→換算年数→重複年度→後の控除調整→課税退職所得→税額",IF(G9="","",IF(I9="対象外","No.2732：確認期間外→重複調整なし→通常控除→課税退職所得→税額","")))) -> No.2735：同年の退職手当等を合算し、2制度の勤続期間を統合して退職所得控除額を計算 | AF9: =IF(OR(J9="",K9="",G9="同年受取"),"",ROUNDDOWN(IF(J9<=8000000,J9/400000,(J9-8000000)/700000+20),0)) | AG9: =IF(OR(J9="",K9="",G9="同年受取"),"",IF(J9<K9,AF9,IF(G9="DC → 会社退職金",入力!$B$21,入力!$B$19))) | AH9: =IF(G9<>"同年受取","",_xlfn.LET( _xlpm.A開始,入力!$B$6, _xlpm.A終了,入力!$B$7, _xlpm.B開始,入力!$B$10, _xlpm.B終了,B9, _xlpm.A日数,_xlpm.A終了-_xlpm.A開始+1, _xlpm.B日数,_xlpm.B終了-_xlpm.B開始+1, IF( OR(_xlpm.A終了<_xlpm.B開始,_xlpm.B終了<_xlpm.A開始), IF(_xlpm.A日数>=_xlpm.B日数, DATEDIF(_xlpm.A開始,_xlpm.A終了+1,"Y")+IF(DATEDIF(_xlpm.A開始,_xlpm.A終了+1,"YD")>0,1,0), DATEDIF(_xlpm.B開始,_xlpm.B終了+1,"Y")+IF(DATEDIF(_xlpm.B開始,_xlpm.B終了+1,"YD")>0,1,0) ), DATEDIF(MIN(_xlpm.A開始,_xlpm.B開始),MAX(_xlpm.A終了,_xlpm.B終了)+1,"Y") +IF(DATEDIF(MIN(_xlpm.A開始,_xlpm.B開始),MAX(_xlpm.A終了,_xlpm.B終了)+1,"YD")>0,1,0) ) )) -> 47 | AI9: =IF(G9<>"同年受取","",IF(AH9<=20,MAX(400000*AH9,800000),8000000+700000*(AH9-20))) -> 26900000 | AJ9: =IF(G9<>"同年受取","",MAX(0,FLOOR((E9+F9-AI9)/2,1000))) -> 0 | AK9: =IF(G9<>"同年受取","",VLOOKUP(AJ9,tabletax,3,TRUE)) -> 0.05 | AL9: =IF(G9<>"同年受取","",VLOOKUP(AJ9,tabletax,4,TRUE)) -> 0 | AM9: =IF(G9<>"同年受取","",FLOOR((AJ9*AK9-AL9)*1.021,1)) -> 0 | AN9: =IF(G9<>"同年受取","",FLOOR(AJ9*0.1,100)) -> 0 | AO9: =IF(G9<>"同年受取","",AM9+AN9) -> 0 | AP9: =IF(G9<>"同年受取","",IF(AM9="","",E9+F9-AO9)) -> 11000000 | AQ9: =IF(AD9<>"",AD9,IF(AP9<>"",AP9)) -> 11000000
A10: 7 | B10: 49856 | C10: 49856 | D10: =入力!$B$8 -> 49459 | E10: =入力!$B$13 -> 10000000 | F10: =入力!$B$9 -> 1000000 | G10: =IF(OR(C10="",D10=""),"",IF(YEAR(C10)=YEAR(D10),"同年受取",IF(C10<D10,"DC → 会社退職金","会社退職金 → DC"))) -> 会社退職金 → DC | H10: =IF(OR(G10="同年受取",G10=""),"",IF(G10="DC → 会社退職金",9,19)) -> 19 | I10: =IF(G10="同年受取","同年合算",IF(G10="","",IF(AND(MIN(C10,D10)<DATE(YEAR(MAX(C10,D10)),1,1),MIN(C10,D10)>=DATE(YEAR(MAX(C10,D10))-H10,1,1)),"対象","対象外"))) -> 対象 | J10: =IF(G10="同年受取","",IF(G10="DC → 会社退職金",E10,IF(G10="会社退職金 → DC",F10,""))) -> 1000000 | K10: =IF(G10="同年受取","", IF(G10="DC → 会社退職金", _xlfn.LET( _xlpm.DC開始,入力!$B$10, _xlpm.DC終了,B10, _xlpm.年数,IF(DATEDIF(_xlpm.DC開始,_xlpm.DC終了+1,"M")=0,1,CEILING(DATEDIF(_xlpm.DC開始,_xlpm.DC終了+1,"M")/12,1)), IF(_xlpm.年数<=20,MAX(400000*_xlpm.年数,800000),8000000+700000*(_xlpm.年数-20)) ), IF(G10="会社退職金 → DC", _xlfn.LET( _xlpm.会社控除額,入力!$B$20, _xlpm.会社控除額 ), ""))) -> 26900000 | L10: =IF(OR(J10="",K10=""),"",IF(J10<K10,"該当","非該当")) -> 該当 | M10: =_xlfn.LET( _xlpm.前判定,L10, _xlpm.前退,J10, _xlpm.前控,K10, _xlpm.会勤年,入力!$B$19, IF(G10="同年受取","", IF(OR(_xlpm.前退="",_xlpm.前控=""),"", IF(_xlpm.前判定="該当", ROUNDDOWN(IF(_xlpm.前退<=8000000,_xlpm.前退/400000,(_xlpm.前退-8000000)/700000+20),0), IF(G10="DC → 会社退職金", _xlfn.LET( _xlpm.DC開始,入力!$B$10, _xlpm.DC終了,B10, DATEDIF(_xlpm.DC開始,_xlpm.DC終了+1,"Y") +IF(DATEDIF(_xlpm.DC開始,_xlpm.DC終了+1,"YD")>0,1,0) ), IF(G10="会社退職金 → DC", _xlpm.会勤年, "" ) ) ) ) ) ) -> 2 | N10: =IF(G10="同年受取","",IF(I10<>"対象","",MAX(IF(G10="DC → 会社退職金",入力!$B$10,入力!$B$6),IF(G10="DC → 会社退職金",入力!$B$6,入力!$B$10)))) -> 44652 | O10: =_xlfn.LET( _xlpm.受取順,G10, _xlpm.対象,I10, _xlpm.前退,J10, _xlpm.前控,K10, _xlpm.前換算年,M10, _xlpm.会社開始,入力!$B$6, _xlpm.会社終了,入力!$B$7, _xlpm.DC開始,入力!$B$10, _xlpm.DC終了,B10, _xlpm.重複終了上限,IF( _xlpm.受取順="DC → 会社退職金", _xlpm.DC終了, _xlpm.会社終了 ), _xlpm.換算期間終了,IF( _xlpm.前退<_xlpm.前控, EDATE( IF( _xlpm.受取順="DC → 会社退職金", _xlpm.DC開始, _xlpm.会社開始 ), _xlpm.前換算年*12 )-1, _xlpm.重複終了上限 ), IF( _xlpm.受取順="同年受取", "", IF( _xlpm.対象<>"対象", "", MIN( _xlpm.重複終了上限, _xlpm.換算期間終了 ) ) ) ) -> 33328 | P10: =_xlfn.LET( _xlpm.重複開始,N10, _xlpm.重複終了,O10, IF( G10="同年受取", "", IF( OR(_xlpm.重複開始="",_xlpm.重複終了="",_xlpm.重複開始>_xlpm.重複終了), 0, DATEDIF(_xlpm.重複開始,_xlpm.重複終了+1,"Y") ) ) ) -> 0 | Q10: =IF(G10="同年受取","", _xlfn.LET( _xlpm.受取順,G10, _xlpm.実重複年,P10, _xlpm.会社本来控除,入力!$B$20, _xlpm.重複控除,IF( _xlpm.実重複年<=20, MAX(800000,400000*_xlpm.実重複年), 8000000+700000*(_xlpm.実重複年-20) ), IF( _xlpm.受取順="DC → 会社退職金", IF( I10="対象", MAX(0,_xlpm.会社本来控除-_xlpm.重複控除), _xlpm.会社本来控除 ), _xlpm.会社本来控除 ) )) -> 26900000 | R10: =IF(G10="同年受取","", _xlfn.LET( _xlpm.受取順,G10, _xlpm.DC開始,入力!$B$10, _xlpm.DC終了,B10, _xlpm.実重複年,P10, _xlpm.DC年数,IF( DATEDIF(_xlpm.DC開始,_xlpm.DC終了+1,"M")=0, 1, CEILING(DATEDIF(_xlpm.DC開始,_xlpm.DC終了+1,"M")/12,1) ), _xlpm.DC本来控除,IF( _xlpm.DC年数<=20, 400000*_xlpm.DC年数, 8000000+700000*(_xlpm.DC年数-20) ), _xlpm.重複控除,IF( _xlpm.実重複年=0, 0, IF( _xlpm.実重複年<=20, 400000*_xlpm.実重複年, 8000000+700000*(_xlpm.実重複年-20) ) ), IF( _xlpm.受取順="会社退職金 → DC", IF( I10="対象", MAX(0,_xlpm.DC本来控除-_xlpm.重複控除), _xlpm.DC本来控除 ), _xlpm.DC本来控除 ) ) ) -> 6000000 | S10: =IF(G10="同年受取","",IF(OR(G10="",G10="同日受取：要確認"),"",ROUNDDOWN(MAX(0,(F10-Q10)/2),-3))) -> 0 | T10: =IF(G10="同年受取","",IF(OR(G10="",G10="同日受取：要確認"),"",ROUNDDOWN(MAX(0,(E10-R10)/2),-3))) -> 2000000 | U10: =IF(OR(G10="同年受取",S10=""),"",VLOOKUP(S10,税率表!$A$2:$C$8,2,TRUE)) -> 0.05 | V10: =IF(U10="","",VLOOKUP(S10,税率表!$A$2:$C$8,3,TRUE)) -> 0 | W10: =IF(U10="","",ROUNDDOWN(MAX(0,S10*U10-V10)*1.021,0)) -> 0 | X10: =IF(OR(G10="同年受取",T10=""),"",VLOOKUP(T10,税率表!$A$2:$C$8,2,TRUE)) -> 0.1 | Y10: =IF(X10="","",VLOOKUP(T10,税率表!$A$2:$C$8,3,TRUE)) -> 97500 | Z10: =IF(X10="","",ROUNDDOWN(MAX(0,T10*X10-Y10)*1.021,0)) -> 104652 | AA10: =IF(G10="同年受取","",IF(S10="","",ROUNDDOWN(S10*10%,0))) -> 0 | AB10: =IF(G10="同年受取","",IF(T10="","",ROUNDDOWN(T10*10%,0))) -> 200000 | AC10: =IF(G10="同年受取","",IF(OR(W10="",Z10=""),"",SUM(W10,Z10,AA10,AB10))) -> 304652 | AD10: =IF(G10="同年受取","",IF(AC10="","",E10+F10-AC10)) -> 10695348 | AE10: =IF(G10="同年受取","No.2735：同年の退職手当等を合算し、2制度の勤続期間を統合して退職所得控除額を計算",IF(I10="対象","No.2732：確認期間→前の金額/控除→換算年数→重複年度→後の控除調整→課税退職所得→税額",IF(G10="","",IF(I10="対象外","No.2732：確認期間外→重複調整なし→通常控除→課税退職所得→税額","")))) -> No.2732：確認期間→前の金額/控除→換算年数→重複年度→後の控除調整→課税退職所得→税額 | AF10: =IF(OR(J10="",K10="",G10="同年受取"),"",ROUNDDOWN(IF(J10<=8000000,J10/400000,(J10-8000000)/700000+20),0)) -> 2 | AG10: =IF(OR(J10="",K10="",G10="同年受取"),"",IF(J10<K10,AF10,IF(G10="DC → 会社退職金",入力!$B$21,入力!$B$19))) -> 2 | AH10: =IF(G10<>"同年受取","",_xlfn.LET( _xlpm.A開始,入力!$B$6, _xlpm.A終了,入力!$B$7, _xlpm.B開始,入力!$B$10, _xlpm.B終了,B10, _xlpm.A日数,_xlpm.A終了-_xlpm.A開始+1, _xlpm.B日数,_xlpm.B終了-_xlpm.B開始+1, IF( OR(_xlpm.A終了<_xlpm.B開始,_xlpm.B終了<_xlpm.A開始), IF(_xlpm.A日数>=_xlpm.B日数, DATEDIF(_xlpm.A開始,_xlpm.A終了+1,"Y")+IF(DATEDIF(_xlpm.A開始,_xlpm.A終了+1,"YD")>0,1,0), DATEDIF(_xlpm.B開始,_xlpm.B終了+1,"Y")+IF(DATEDIF(_xlpm.B開始,_xlpm.B終了+1,"YD")>0,1,0) ), DATEDIF(MIN(_xlpm.A開始,_xlpm.B開始),MAX(_xlpm.A終了,_xlpm.B終了)+1,"Y") +IF(DATEDIF(MIN(_xlpm.A開始,_xlpm.B開始),MAX(_xlpm.A終了,_xlpm.B終了)+1,"YD")>0,1,0) ) )) | AI10: =IF(G10<>"同年受取","",IF(AH10<=20,MAX(400000*AH10,800000),8000000+700000*(AH10-20))) | AJ10: =IF(G10<>"同年受取","",MAX(0,FLOOR((E10+F10-AI10)/2,1000))) | AK10: =IF(G10<>"同年受取","",VLOOKUP(AJ10,tabletax,3,TRUE)) | AL10: =IF(G10<>"同年受取","",VLOOKUP(AJ10,tabletax,4,TRUE)) | AM10: =IF(G10<>"同年受取","",FLOOR((AJ10*AK10-AL10)*1.021,1)) | AN10: =IF(G10<>"同年受取","",FLOOR(AJ10*0.1,100)) | AO10: =IF(G10<>"同年受取","",AM10+AN10) | AP10: =IF(G10<>"同年受取","",IF(AM10="","",E10+F10-AO10)) | AQ10: =IF(AD10<>"",AD10,IF(AP10<>"",AP10)) -> 10695348
A11: 8 | B11: 50221 | C11: 50221 | D11: =入力!$B$8 -> 49459 | E11: =入力!$B$13 -> 10000000 | F11: =入力!$B$9 -> 1000000 | G11: =IF(OR(C11="",D11=""),"",IF(YEAR(C11)=YEAR(D11),"同年受取",IF(C11<D11,"DC → 会社退職金","会社退職金 → DC"))) -> 会社退職金 → DC | H11: =IF(OR(G11="同年受取",G11=""),"",IF(G11="DC → 会社退職金",9,19)) -> 19 | I11: =IF(G11="同年受取","同年合算",IF(G11="","",IF(AND(MIN(C11,D11)<DATE(YEAR(MAX(C11,D11)),1,1),MIN(C11,D11)>=DATE(YEAR(MAX(C11,D11))-H11,1,1)),"対象","対象外"))) -> 対象 | J11: =IF(G11="同年受取","",IF(G11="DC → 会社退職金",E11,IF(G11="会社退職金 → DC",F11,""))) -> 1000000 | K11: =IF(G11="同年受取","", IF(G11="DC → 会社退職金", _xlfn.LET( _xlpm.DC開始,入力!$B$10, _xlpm.DC終了,B11, _xlpm.年数,IF(DATEDIF(_xlpm.DC開始,_xlpm.DC終了+1,"M")=0,1,CEILING(DATEDIF(_xlpm.DC開始,_xlpm.DC終了+1,"M")/12,1)), IF(_xlpm.年数<=20,MAX(400000*_xlpm.年数,800000),8000000+700000*(_xlpm.年数-20)) ), IF(G11="会社退職金 → DC", _xlfn.LET( _xlpm.会社控除額,入力!$B$20, _xlpm.会社控除額 ), ""))) -> 26900000 | L11: =IF(OR(J11="",K11=""),"",IF(J11<K11,"該当","非該当")) -> 該当 | M11: =_xlfn.LET( _xlpm.前判定,L11, _xlpm.前退,J11, _xlpm.前控,K11, _xlpm.会勤年,入力!$B$19, IF(G11="同年受取","", IF(OR(_xlpm.前退="",_xlpm.前控=""),"", IF(_xlpm.前判定="該当", ROUNDDOWN(IF(_xlpm.前退<=8000000,_xlpm.前退/400000,(_xlpm.前退-8000000)/700000+20),0), IF(G11="DC → 会社退職金", _xlfn.LET( _xlpm.DC開始,入力!$B$10, _xlpm.DC終了,B11, DATEDIF(_xlpm.DC開始,_xlpm.DC終了+1,"Y") +IF(DATEDIF(_xlpm.DC開始,_xlpm.DC終了+1,"YD")>0,1,0) ), IF(G11="会社退職金 → DC", _xlpm.会勤年, "" ) ) ) ) ) ) -> 2 | N11: =IF(G11="同年受取","",IF(I11<>"対象","",MAX(IF(G11="DC → 会社退職金",入力!$B$10,入力!$B$6),IF(G11="DC → 会社退職金",入力!$B$6,入力!$B$10)))) -> 44652 | O11: =_xlfn.LET( _xlpm.受取順,G11, _xlpm.対象,I11, _xlpm.前退,J11, _xlpm.前控,K11, _xlpm.前換算年,M11, _xlpm.会社開始,入力!$B$6, _xlpm.会社終了,入力!$B$7, _xlpm.DC開始,入力!$B$10, _xlpm.DC終了,B11, _xlpm.重複終了上限,IF( _xlpm.受取順="DC → 会社退職金", _xlpm.DC終了, _xlpm.会社終了 ), _xlpm.換算期間終了,IF( _xlpm.前退<_xlpm.前控, EDATE( IF( _xlpm.受取順="DC → 会社退職金", _xlpm.DC開始, _xlpm.会社開始 ), _xlpm.前換算年*12 )-1, _xlpm.重複終了上限 ), IF( _xlpm.受取順="同年受取", "", IF( _xlpm.対象<>"対象", "", MIN( _xlpm.重複終了上限, _xlpm.換算期間終了 ) ) ) ) -> 33328 | P11: =_xlfn.LET( _xlpm.重複開始,N11, _xlpm.重複終了,O11, IF( G11="同年受取", "", IF( OR(_xlpm.重複開始="",_xlpm.重複終了="",_xlpm.重複開始>_xlpm.重複終了), 0, DATEDIF(_xlpm.重複開始,_xlpm.重複終了+1,"Y") ) ) ) -> 0 | Q11: =IF(G11="同年受取","", _xlfn.LET( _xlpm.受取順,G11, _xlpm.実重複年,P11, _xlpm.会社本来控除,入力!$B$20, _xlpm.重複控除,IF( _xlpm.実重複年<=20, MAX(800000,400000*_xlpm.実重複年), 8000000+700000*(_xlpm.実重複年-20) ), IF( _xlpm.受取順="DC → 会社退職金", IF( I11="対象", MAX(0,_xlpm.会社本来控除-_xlpm.重複控除), _xlpm.会社本来控除 ), _xlpm.会社本来控除 ) )) -> 26900000 | R11: =IF(G11="同年受取","", _xlfn.LET( _xlpm.受取順,G11, _xlpm.DC開始,入力!$B$10, _xlpm.DC終了,B11, _xlpm.実重複年,P11, _xlpm.DC年数,IF( DATEDIF(_xlpm.DC開始,_xlpm.DC終了+1,"M")=0, 1, CEILING(DATEDIF(_xlpm.DC開始,_xlpm.DC終了+1,"M")/12,1) ), _xlpm.DC本来控除,IF( _xlpm.DC年数<=20, 400000*_xlpm.DC年数, 8000000+700000*(_xlpm.DC年数-20) ), _xlpm.重複控除,IF( _xlpm.実重複年=0, 0, IF( _xlpm.実重複年<=20, 400000*_xlpm.実重複年, 8000000+700000*(_xlpm.実重複年-20) ) ), IF( _xlpm.受取順="会社退職金 → DC", IF( I11="対象", MAX(0,_xlpm.DC本来控除-_xlpm.重複控除), _xlpm.DC本来控除 ), _xlpm.DC本来控除 ) ) ) -> 6400000 | S11: =IF(G11="同年受取","",IF(OR(G11="",G11="同日受取：要確認"),"",ROUNDDOWN(MAX(0,(F11-Q11)/2),-3))) -> 0 | T11: =IF(G11="同年受取","",IF(OR(G11="",G11="同日受取：要確認"),"",ROUNDDOWN(MAX(0,(E11-R11)/2),-3))) -> 1800000 | U11: =IF(OR(G11="同年受取",S11=""),"",VLOOKUP(S11,税率表!$A$2:$C$8,2,TRUE)) -> 0.05 | V11: =IF(U11="","",VLOOKUP(S11,税率表!$A$2:$C$8,3,TRUE)) -> 0 | W11: =IF(U11="","",ROUNDDOWN(MAX(0,S11*U11-V11)*1.021,0)) -> 0 | X11: =IF(OR(G11="同年受取",T11=""),"",VLOOKUP(T11,税率表!$A$2:$C$8,2,TRUE)) -> 0.05 | Y11: =IF(X11="","",VLOOKUP(T11,税率表!$A$2:$C$8,3,TRUE)) -> 0 | Z11: =IF(X11="","",ROUNDDOWN(MAX(0,T11*X11-Y11)*1.021,0)) -> 91890 | AA11: =IF(G11="同年受取","",IF(S11="","",ROUNDDOWN(S11*10%,0))) -> 0 | AB11: =IF(G11="同年受取","",IF(T11="","",ROUNDDOWN(T11*10%,0))) -> 180000 | AC11: =IF(G11="同年受取","",IF(OR(W11="",Z11=""),"",SUM(W11,Z11,AA11,AB11))) -> 271890 | AD11: =IF(G11="同年受取","",IF(AC11="","",E11+F11-AC11)) -> 10728110 | AE11: =IF(G11="同年受取","No.2735：同年の退職手当等を合算し、2制度の勤続期間を統合して退職所得控除額を計算",IF(I11="対象","No.2732：確認期間→前の金額/控除→換算年数→重複年度→後の控除調整→課税退職所得→税額",IF(G11="","",IF(I11="対象外","No.2732：確認期間外→重複調整なし→通常控除→課税退職所得→税額","")))) -> No.2732：確認期間→前の金額/控除→換算年数→重複年度→後の控除調整→課税退職所得→税額 | AF11: =IF(OR(J11="",K11="",G11="同年受取"),"",ROUNDDOWN(IF(J11<=8000000,J11/400000,(J11-8000000)/700000+20),0)) -> 2 | AG11: =IF(OR(J11="",K11="",G11="同年受取"),"",IF(J11<K11,AF11,IF(G11="DC → 会社退職金",入力!$B$21,入力!$B$19))) -> 2 | AH11: =IF(G11<>"同年受取","",_xlfn.LET( _xlpm.A開始,入力!$B$6, _xlpm.A終了,入力!$B$7, _xlpm.B開始,入力!$B$10, _xlpm.B終了,B11, _xlpm.A日数,_xlpm.A終了-_xlpm.A開始+1, _xlpm.B日数,_xlpm.B終了-_xlpm.B開始+1, IF( OR(_xlpm.A終了<_xlpm.B開始,_xlpm.B終了<_xlpm.A開始), IF(_xlpm.A日数>=_xlpm.B日数, DATEDIF(_xlpm.A開始,_xlpm.A終了+1,"Y")+IF(DATEDIF(_xlpm.A開始,_xlpm.A終了+1,"YD")>0,1,0), DATEDIF(_xlpm.B開始,_xlpm.B終了+1,"Y")+IF(DATEDIF(_xlpm.B開始,_xlpm.B終了+1,"YD")>0,1,0) ), DATEDIF(MIN(_xlpm.A開始,_xlpm.B開始),MAX(_xlpm.A終了,_xlpm.B終了)+1,"Y") +IF(DATEDIF(MIN(_xlpm.A開始,_xlpm.B開始),MAX(_xlpm.A終了,_xlpm.B終了)+1,"YD")>0,1,0) ) )) | AI11: =IF(G11<>"同年受取","",IF(AH11<=20,MAX(400000*AH11,800000),8000000+700000*(AH11-20))) | AJ11: =IF(G11<>"同年受取","",MAX(0,FLOOR((E11+F11-AI11)/2,1000))) | AK11: =IF(G11<>"同年受取","",VLOOKUP(AJ11,tabletax,3,TRUE)) | AL11: =IF(G11<>"同年受取","",VLOOKUP(AJ11,tabletax,4,TRUE)) | AM11: =IF(G11<>"同年受取","",FLOOR((AJ11*AK11-AL11)*1.021,1)) | AN11: =IF(G11<>"同年受取","",FLOOR(AJ11*0.1,100)) | AO11: =IF(G11<>"同年受取","",AM11+AN11) | AP11: =IF(G11<>"同年受取","",IF(AM11="","",E11+F11-AO11)) | AQ11: =IF(AD11<>"",AD11,IF(AP11<>"",AP11)) -> 10728110
A12: 9 | B12: 50586 | C12: 50586 | D12: =入力!$B$8 -> 49459 | E12: =入力!$B$13 -> 10000000 | F12: =入力!$B$9 -> 1000000 | G12: =IF(OR(C12="",D12=""),"",IF(YEAR(C12)=YEAR(D12),"同年受取",IF(C12<D12,"DC → 会社退職金","会社退職金 → DC"))) -> 会社退職金 → DC | H12: =IF(OR(G12="同年受取",G12=""),"",IF(G12="DC → 会社退職金",9,19)) -> 19 | I12: =IF(G12="同年受取","同年合算",IF(G12="","",IF(AND(MIN(C12,D12)<DATE(YEAR(MAX(C12,D12)),1,1),MIN(C12,D12)>=DATE(YEAR(MAX(C12,D12))-H12,1,1)),"対象","対象外"))) -> 対象 | J12: =IF(G12="同年受取","",IF(G12="DC → 会社退職金",E12,IF(G12="会社退職金 → DC",F12,""))) -> 1000000 | K12: =IF(G12="同年受取","", IF(G12="DC → 会社退職金", _xlfn.LET( _xlpm.DC開始,入力!$B$10, _xlpm.DC終了,B12, _xlpm.年数,IF(DATEDIF(_xlpm.DC開始,_xlpm.DC終了+1,"M")=0,1,CEILING(DATEDIF(_xlpm.DC開始,_xlpm.DC終了+1,"M")/12,1)), IF(_xlpm.年数<=20,MAX(400000*_xlpm.年数,800000),8000000+700000*(_xlpm.年数-20)) ), IF(G12="会社退職金 → DC", _xlfn.LET( _xlpm.会社控除額,入力!$B$20, _xlpm.会社控除額 ), ""))) -> 26900000 | L12: =IF(OR(J12="",K12=""),"",IF(J12<K12,"該当","非該当")) -> 該当 | M12: =_xlfn.LET( _xlpm.前判定,L12, _xlpm.前退,J12, _xlpm.前控,K12, _xlpm.会勤年,入力!$B$19, IF(G12="同年受取","", IF(OR(_xlpm.前退="",_xlpm.前控=""),"", IF(_xlpm.前判定="該当", ROUNDDOWN(IF(_xlpm.前退<=8000000,_xlpm.前退/400000,(_xlpm.前退-8000000)/700000+20),0), IF(G12="DC → 会社退職金", _xlfn.LET( _xlpm.DC開始,入力!$B$10, _xlpm.DC終了,B12, DATEDIF(_xlpm.DC開始,_xlpm.DC終了+1,"Y") +IF(DATEDIF(_xlpm.DC開始,_xlpm.DC終了+1,"YD")>0,1,0) ), IF(G12="会社退職金 → DC", _xlpm.会勤年, "" ) ) ) ) ) ) -> 2 | N12: =IF(G12="同年受取","",IF(I12<>"対象","",MAX(IF(G12="DC → 会社退職金",入力!$B$10,入力!$B$6),IF(G12="DC → 会社退職金",入力!$B$6,入力!$B$10)))) -> 44652 | O12: =_xlfn.LET( _xlpm.受取順,G12, _xlpm.対象,I12, _xlpm.前退,J12, _xlpm.前控,K12, _xlpm.前換算年,M12, _xlpm.会社開始,入力!$B$6, _xlpm.会社終了,入力!$B$7, _xlpm.DC開始,入力!$B$10, _xlpm.DC終了,B12, _xlpm.重複終了上限,IF( _xlpm.受取順="DC → 会社退職金", _xlpm.DC終了, _xlpm.会社終了 ), _xlpm.換算期間終了,IF( _xlpm.前退<_xlpm.前控, EDATE( IF( _xlpm.受取順="DC → 会社退職金", _xlpm.DC開始, _xlpm.会社開始 ), _xlpm.前換算年*12 )-1, _xlpm.重複終了上限 ), IF( _xlpm.受取順="同年受取", "", IF( _xlpm.対象<>"対象", "", MIN( _xlpm.重複終了上限, _xlpm.換算期間終了 ) ) ) ) -> 33328 | P12: =_xlfn.LET( _xlpm.重複開始,N12, _xlpm.重複終了,O12, IF( G12="同年受取", "", IF( OR(_xlpm.重複開始="",_xlpm.重複終了="",_xlpm.重複開始>_xlpm.重複終了), 0, DATEDIF(_xlpm.重複開始,_xlpm.重複終了+1,"Y") ) ) ) -> 0 | Q12: =IF(G12="同年受取","", _xlfn.LET( _xlpm.受取順,G12, _xlpm.実重複年,P12, _xlpm.会社本来控除,入力!$B$20, _xlpm.重複控除,IF( _xlpm.実重複年<=20, MAX(800000,400000*_xlpm.実重複年), 8000000+700000*(_xlpm.実重複年-20) ), IF( _xlpm.受取順="DC → 会社退職金", IF( I12="対象", MAX(0,_xlpm.会社本来控除-_xlpm.重複控除), _xlpm.会社本来控除 ), _xlpm.会社本来控除 ) )) -> 26900000 | R12: =IF(G12="同年受取","", _xlfn.LET( _xlpm.受取順,G12, _xlpm.DC開始,入力!$B$10, _xlpm.DC終了,B12, _xlpm.実重複年,P12, _xlpm.DC年数,IF( DATEDIF(_xlpm.DC開始,_xlpm.DC終了+1,"M")=0, 1, CEILING(DATEDIF(_xlpm.DC開始,_xlpm.DC終了+1,"M")/12,1) ), _xlpm.DC本来控除,IF( _xlpm.DC年数<=20, 400000*_xlpm.DC年数, 8000000+700000*(_xlpm.DC年数-20) ), _xlpm.重複控除,IF( _xlpm.実重複年=0, 0, IF( _xlpm.実重複年<=20, 400000*_xlpm.実重複年, 8000000+700000*(_xlpm.実重複年-20) ) ), IF( _xlpm.受取順="会社退職金 → DC", IF( I12="対象", MAX(0,_xlpm.DC本来控除-_xlpm.重複控除), _xlpm.DC本来控除 ), _xlpm.DC本来控除 ) ) ) -> 6800000 | S12: =IF(G12="同年受取","",IF(OR(G12="",G12="同日受取：要確認"),"",ROUNDDOWN(MAX(0,(F12-Q12)/2),-3))) -> 0 | T12: =IF(G12="同年受取","",IF(OR(G12="",G12="同日受取：要確認"),"",ROUNDDOWN(MAX(0,(E12-R12)/2),-3))) -> 1600000 | U12: =IF(OR(G12="同年受取",S12=""),"",VLOOKUP(S12,税率表!$A$2:$C$8,2,TRUE)) -> 0.05 | V12: =IF(U12="","",VLOOKUP(S12,税率表!$A$2:$C$8,3,TRUE)) -> 0 | W12: =IF(U12="","",ROUNDDOWN(MAX(0,S12*U12-V12)*1.021,0)) -> 0 | X12: =IF(OR(G12="同年受取",T12=""),"",VLOOKUP(T12,税率表!$A$2:$C$8,2,TRUE)) -> 0.05 | Y12: =IF(X12="","",VLOOKUP(T12,税率表!$A$2:$C$8,3,TRUE)) -> 0 | Z12: =IF(X12="","",ROUNDDOWN(MAX(0,T12*X12-Y12)*1.021,0)) -> 81680 | AA12: =IF(G12="同年受取","",IF(S12="","",ROUNDDOWN(S12*10%,0))) -> 0 | AB12: =IF(G12="同年受取","",IF(T12="","",ROUNDDOWN(T12*10%,0))) -> 160000 | AC12: =IF(G12="同年受取","",IF(OR(W12="",Z12=""),"",SUM(W12,Z12,AA12,AB12))) -> 241680 | AD12: =IF(G12="同年受取","",IF(AC12="","",E12+F12-AC12)) -> 10758320 | AE12: =IF(G12="同年受取","No.2735：同年の退職手当等を合算し、2制度の勤続期間を統合して退職所得控除額を計算",IF(I12="対象","No.2732：確認期間→前の金額/控除→換算年数→重複年度→後の控除調整→課税退職所得→税額",IF(G12="","",IF(I12="対象外","No.2732：確認期間外→重複調整なし→通常控除→課税退職所得→税額","")))) -> No.2732：確認期間→前の金額/控除→換算年数→重複年度→後の控除調整→課税退職所得→税額 | AF12: =IF(OR(J12="",K12="",G12="同年受取"),"",ROUNDDOWN(IF(J12<=8000000,J12/400000,(J12-8000000)/700000+20),0)) -> 2 | AG12: =IF(OR(J12="",K12="",G12="同年受取"),"",IF(J12<K12,AF12,IF(G12="DC → 会社退職金",入力!$B$21,入力!$B$19))) -> 2 | AH12: =IF(G12<>"同年受取","",_xlfn.LET( _xlpm.A開始,入力!$B$6, _xlpm.A終了,入力!$B$7, _xlpm.B開始,入力!$B$10, _xlpm.B終了,B12, _xlpm.A日数,_xlpm.A終了-_xlpm.A開始+1, _xlpm.B日数,_xlpm.B終了-_xlpm.B開始+1, IF( OR(_xlpm.A終了<_xlpm.B開始,_xlpm.B終了<_xlpm.A開始), IF(_xlpm.A日数>=_xlpm.B日数, DATEDIF(_xlpm.A開始,_xlpm.A終了+1,"Y")+IF(DATEDIF(_xlpm.A開始,_xlpm.A終了+1,"YD")>0,1,0), DATEDIF(_xlpm.B開始,_xlpm.B終了+1,"Y")+IF(DATEDIF(_xlpm.B開始,_xlpm.B終了+1,"YD")>0,1,0) ), DATEDIF(MIN(_xlpm.A開始,_xlpm.B開始),MAX(_xlpm.A終了,_xlpm.B終了)+1,"Y") +IF(DATEDIF(MIN(_xlpm.A開始,_xlpm.B開始),MAX(_xlpm.A終了,_xlpm.B終了)+1,"YD")>0,1,0) ) )) | AI12: =IF(G12<>"同年受取","",IF(AH12<=20,MAX(400000*AH12,800000),8000000+700000*(AH12-20))) | AJ12: =IF(G12<>"同年受取","",MAX(0,FLOOR((E12+F12-AI12)/2,1000))) | AK12: =IF(G12<>"同年受取","",VLOOKUP(AJ12,tabletax,3,TRUE)) | AL12: =IF(G12<>"同年受取","",VLOOKUP(AJ12,tabletax,4,TRUE)) | AM12: =IF(G12<>"同年受取","",FLOOR((AJ12*AK12-AL12)*1.021,1)) | AN12: =IF(G12<>"同年受取","",FLOOR(AJ12*0.1,100)) | AO12: =IF(G12<>"同年受取","",AM12+AN12) | AP12: =IF(G12<>"同年受取","",IF(AM12="","",E12+F12-AO12)) | AQ12: =IF(AD12<>"",AD12,IF(AP12<>"",AP12)) -> 10758320
A13: 10 | B13: 50951 | C13: 50951 | D13: =入力!$B$8 -> 49459 | E13: =入力!$B$13 -> 10000000 | F13: =入力!$B$9 -> 1000000 | G13: =IF(OR(C13="",D13=""),"",IF(YEAR(C13)=YEAR(D13),"同年受取",IF(C13<D13,"DC → 会社退職金","会社退職金 → DC"))) -> 会社退職金 → DC | H13: =IF(OR(G13="同年受取",G13=""),"",IF(G13="DC → 会社退職金",9,19)) -> 19 | I13: =IF(G13="同年受取","同年合算",IF(G13="","",IF(AND(MIN(C13,D13)<DATE(YEAR(MAX(C13,D13)),1,1),MIN(C13,D13)>=DATE(YEAR(MAX(C13,D13))-H13,1,1)),"対象","対象外"))) -> 対象 | J13: =IF(G13="同年受取","",IF(G13="DC → 会社退職金",E13,IF(G13="会社退職金 → DC",F13,""))) -> 1000000 | K13: =IF(G13="同年受取","", IF(G13="DC → 会社退職金", _xlfn.LET( _xlpm.DC開始,入力!$B$10, _xlpm.DC終了,B13, _xlpm.年数,IF(DATEDIF(_xlpm.DC開始,_xlpm.DC終了+1,"M")=0,1,CEILING(DATEDIF(_xlpm.DC開始,_xlpm.DC終了+1,"M")/12,1)), IF(_xlpm.年数<=20,MAX(400000*_xlpm.年数,800000),8000000+700000*(_xlpm.年数-20)) ), IF(G13="会社退職金 → DC", _xlfn.LET( _xlpm.会社控除額,入力!$B$20, _xlpm.会社控除額 ), ""))) -> 26900000 | L13: =IF(OR(J13="",K13=""),"",IF(J13<K13,"該当","非該当")) -> 該当 | M13: =_xlfn.LET( _xlpm.前判定,L13, _xlpm.前退,J13, _xlpm.前控,K13, _xlpm.会勤年,入力!$B$19, IF(G13="同年受取","", IF(OR(_xlpm.前退="",_xlpm.前控=""),"", IF(_xlpm.前判定="該当", ROUNDDOWN(IF(_xlpm.前退<=8000000,_xlpm.前退/400000,(_xlpm.前退-8000000)/700000+20),0), IF(G13="DC → 会社退職金", _xlfn.LET( _xlpm.DC開始,入力!$B$10, _xlpm.DC終了,B13, DATEDIF(_xlpm.DC開始,_xlpm.DC終了+1,"Y") +IF(DATEDIF(_xlpm.DC開始,_xlpm.DC終了+1,"YD")>0,1,0) ), IF(G13="会社退職金 → DC", _xlpm.会勤年, "" ) ) ) ) ) ) -> 2 | N13: =IF(G13="同年受取","",IF(I13<>"対象","",MAX(IF(G13="DC → 会社退職金",入力!$B$10,入力!$B$6),IF(G13="DC → 会社退職金",入力!$B$6,入力!$B$10)))) -> 44652 | O13: =_xlfn.LET( _xlpm.受取順,G13, _xlpm.対象,I13, _xlpm.前退,J13, _xlpm.前控,K13, _xlpm.前換算年,M13, _xlpm.会社開始,入力!$B$6, _xlpm.会社終了,入力!$B$7, _xlpm.DC開始,入力!$B$10, _xlpm.DC終了,B13, _xlpm.重複終了上限,IF( _xlpm.受取順="DC → 会社退職金", _xlpm.DC終了, _xlpm.会社終了 ), _xlpm.換算期間終了,IF( _xlpm.前退<_xlpm.前控, EDATE( IF( _xlpm.受取順="DC → 会社退職金", _xlpm.DC開始, _xlpm.会社開始 ), _xlpm.前換算年*12 )-1, _xlpm.重複終了上限 ), IF( _xlpm.受取順="同年受取", "", IF( _xlpm.対象<>"対象", "", MIN( _xlpm.重複終了上限, _xlpm.換算期間終了 ) ) ) ) -> 33328 | P13: =_xlfn.LET( _xlpm.重複開始,N13, _xlpm.重複終了,O13, IF( G13="同年受取", "", IF( OR(_xlpm.重複開始="",_xlpm.重複終了="",_xlpm.重複開始>_xlpm.重複終了), 0, DATEDIF(_xlpm.重複開始,_xlpm.重複終了+1,"Y") ) ) ) -> 0 | Q13: =IF(G13="同年受取","", _xlfn.LET( _xlpm.受取順,G13, _xlpm.実重複年,P13, _xlpm.会社本来控除,入力!$B$20, _xlpm.重複控除,IF( _xlpm.実重複年<=20, MAX(800000,400000*_xlpm.実重複年), 8000000+700000*(_xlpm.実重複年-20) ), IF( _xlpm.受取順="DC → 会社退職金", IF( I13="対象", MAX(0,_xlpm.会社本来控除-_xlpm.重複控除), _xlpm.会社本来控除 ), _xlpm.会社本来控除 ) )) -> 26900000 | R13: =IF(G13="同年受取","", _xlfn.LET( _xlpm.受取順,G13, _xlpm.DC開始,入力!$B$10, _xlpm.DC終了,B13, _xlpm.実重複年,P13, _xlpm.DC年数,IF( DATEDIF(_xlpm.DC開始,_xlpm.DC終了+1,"M")=0, 1, CEILING(DATEDIF(_xlpm.DC開始,_xlpm.DC終了+1,"M")/12,1) ), _xlpm.DC本来控除,IF( _xlpm.DC年数<=20, 400000*_xlpm.DC年数, 8000000+700000*(_xlpm.DC年数-20) ), _xlpm.重複控除,IF( _xlpm.実重複年=0, 0, IF( _xlpm.実重複年<=20, 400000*_xlpm.実重複年, 8000000+700000*(_xlpm.実重複年-20) ) ), IF( _xlpm.受取順="会社退職金 → DC", IF( I13="対象", MAX(0,_xlpm.DC本来控除-_xlpm.重複控除), _xlpm.DC本来控除 ), _xlpm.DC本来控除 ) ) ) -> 7200000 | S13: =IF(G13="同年受取","",IF(OR(G13="",G13="同日受取：要確認"),"",ROUNDDOWN(MAX(0,(F13-Q13)/2),-3))) -> 0 | T13: =IF(G13="同年受取","",IF(OR(G13="",G13="同日受取：要確認"),"",ROUNDDOWN(MAX(0,(E13-R13)/2),-3))) -> 1400000 | U13: =IF(OR(G13="同年受取",S13=""),"",VLOOKUP(S13,税率表!$A$2:$C$8,2,TRUE)) -> 0.05 | V13: =IF(U13="","",VLOOKUP(S13,税率表!$A$2:$C$8,3,TRUE)) -> 0 | W13: =IF(U13="","",ROUNDDOWN(MAX(0,S13*U13-V13)*1.021,0)) -> 0 | X13: =IF(OR(G13="同年受取",T13=""),"",VLOOKUP(T13,税率表!$A$2:$C$8,2,TRUE)) -> 0.05 | Y13: =IF(X13="","",VLOOKUP(T13,税率表!$A$2:$C$8,3,TRUE)) -> 0 | Z13: =IF(X13="","",ROUNDDOWN(MAX(0,T13*X13-Y13)*1.021,0)) -> 71470 | AA13: =IF(G13="同年受取","",IF(S13="","",ROUNDDOWN(S13*10%,0))) -> 0 | AB13: =IF(G13="同年受取","",IF(T13="","",ROUNDDOWN(T13*10%,0))) -> 140000 | AC13: =IF(G13="同年受取","",IF(OR(W13="",Z13=""),"",SUM(W13,Z13,AA13,AB13))) -> 211470 | AD13: =IF(G13="同年受取","",IF(AC13="","",E13+F13-AC13)) -> 10788530 | AE13: =IF(G13="同年受取","No.2735：同年の退職手当等を合算し、2制度の勤続期間を統合して退職所得控除額を計算",IF(I13="対象","No.2732：確認期間→前の金額/控除→換算年数→重複年度→後の控除調整→課税退職所得→税額",IF(G13="","",IF(I13="対象外","No.2732：確認期間外→重複調整なし→通常控除→課税退職所得→税額","")))) -> No.2732：確認期間→前の金額/控除→換算年数→重複年度→後の控除調整→課税退職所得→税額 | AF13: =IF(OR(J13="",K13="",G13="同年受取"),"",ROUNDDOWN(IF(J13<=8000000,J13/400000,(J13-8000000)/700000+20),0)) -> 2 | AG13: =IF(OR(J13="",K13="",G13="同年受取"),"",IF(J13<K13,AF13,IF(G13="DC → 会社退職金",入力!$B$21,入力!$B$19))) -> 2 | AH13: =IF(G13<>"同年受取","",_xlfn.LET( _xlpm.A開始,入力!$B$6, _xlpm.A終了,入力!$B$7, _xlpm.B開始,入力!$B$10, _xlpm.B終了,B13, _xlpm.A日数,_xlpm.A終了-_xlpm.A開始+1, _xlpm.B日数,_xlpm.B終了-_xlpm.B開始+1, IF( OR(_xlpm.A終了<_xlpm.B開始,_xlpm.B終了<_xlpm.A開始), IF(_xlpm.A日数>=_xlpm.B日数, DATEDIF(_xlpm.A開始,_xlpm.A終了+1,"Y")+IF(DATEDIF(_xlpm.A開始,_xlpm.A終了+1,"YD")>0,1,0), DATEDIF(_xlpm.B開始,_xlpm.B終了+1,"Y")+IF(DATEDIF(_xlpm.B開始,_xlpm.B終了+1,"YD")>0,1,0) ), DATEDIF(MIN(_xlpm.A開始,_xlpm.B開始),MAX(_xlpm.A終了,_xlpm.B終了)+1,"Y") +IF(DATEDIF(MIN(_xlpm.A開始,_xlpm.B開始),MAX(_xlpm.A終了,_xlpm.B終了)+1,"YD")>0,1,0) ) )) | AI13: =IF(G13<>"同年受取","",IF(AH13<=20,MAX(400000*AH13,800000),8000000+700000*(AH13-20))) | AJ13: =IF(G13<>"同年受取","",MAX(0,FLOOR((E13+F13-AI13)/2,1000))) | AK13: =IF(G13<>"同年受取","",VLOOKUP(AJ13,tabletax,3,TRUE)) | AL13: =IF(G13<>"同年受取","",VLOOKUP(AJ13,tabletax,4,TRUE)) | AM13: =IF(G13<>"同年受取","",FLOOR((AJ13*AK13-AL13)*1.021,1)) | AN13: =IF(G13<>"同年受取","",FLOOR(AJ13*0.1,100)) | AO13: =IF(G13<>"同年受取","",AM13+AN13) | AP13: =IF(G13<>"同年受取","",IF(AM13="","",E13+F13-AO13)) | AQ13: =IF(AD13<>"",AD13,IF(AP13<>"",AP13)) -> 10788530
A15: 計算式・制度根拠（国税庁 No.2732）
